[2024-08-13 05:18:16] [INFO    ] discord.client: logging in using static token
[2024-08-13 05:19:11] [INFO    ] discord.gateway: Shard ID 0 has connected to Gateway (Session ID: ffb6b432c2565a5543c3609af4f3a3e0).
[2024-08-13 05:19:11] [ERROR   ] discord.client: Ignoring exception in on_message
Traceback (most recent call last):
  File "/root/miniconda3/lib/python3.12/site-packages/discord/client.py", line 450, in _run_event
    await coro(*args, **kwargs)
  File "/root/AkariBot/events/messages.py", line 383, in imageonly_check
    if await self.bot.db.fetchrow(
       ^^^^^^^^^^^^^^^^^^^^^^^^^^^
  File "/root/miniconda3/lib/python3.12/site-packages/asyncpg/pool.py", line 601, in fetchrow
    return await con.fetchrow(
           ^^^^^^^^^^^^^^^^^^^
  File "/root/miniconda3/lib/python3.12/site-packages/asyncpg/connection.py", line 749, in fetchrow
    data = await self._execute(
           ^^^^^^^^^^^^^^^^^^^^
  File "/root/miniconda3/lib/python3.12/site-packages/asyncpg/connection.py", line 1794, in _execute
    result, _ = await self.__execute(
                ^^^^^^^^^^^^^^^^^^^^^
  File "/root/miniconda3/lib/python3.12/site-packages/asyncpg/connection.py", line 1892, in __execute
    result, stmt = await self._do_execute(
                   ^^^^^^^^^^^^^^^^^^^^^^^
  File "/root/miniconda3/lib/python3.12/site-packages/asyncpg/connection.py", line 1925, in _do_execute
    stmt = await self._get_statement(
           ^^^^^^^^^^^^^^^^^^^^^^^^^^
  File "/root/miniconda3/lib/python3.12/site-packages/asyncpg/connection.py", line 433, in _get_statement
    statement = await self._protocol.prepare(
                ^^^^^^^^^^^^^^^^^^^^^^^^^^^^^
  File "asyncpg/protocol/protocol.pyx", line 166, in prepare
asyncpg.exceptions.UndefinedTableError: relation "imgonly" does not exist
[2024-08-13 05:19:12] [ERROR   ] discord.client: Ignoring exception in on_message
Traceback (most recent call last):
  File "/root/miniconda3/lib/python3.12/site-packages/discord/client.py", line 450, in _run_event
    await coro(*args, **kwargs)
  File "/root/AkariBot/events/messages.py", line 383, in imageonly_check
    if await self.bot.db.fetchrow(
       ^^^^^^^^^^^^^^^^^^^^^^^^^^^
  File "/root/miniconda3/lib/python3.12/site-packages/asyncpg/pool.py", line 601, in fetchrow
    return await con.fetchrow(
           ^^^^^^^^^^^^^^^^^^^
  File "/root/miniconda3/lib/python3.12/site-packages/asyncpg/connection.py", line 749, in fetchrow
    data = await self._execute(
           ^^^^^^^^^^^^^^^^^^^^
  File "/root/miniconda3/lib/python3.12/site-packages/asyncpg/connection.py", line 1794, in _execute
    result, _ = await self.__execute(
                ^^^^^^^^^^^^^^^^^^^^^
  File "/root/miniconda3/lib/python3.12/site-packages/asyncpg/connection.py", line 1892, in __execute
    result, stmt = await self._do_execute(
                   ^^^^^^^^^^^^^^^^^^^^^^^
  File "/root/miniconda3/lib/python3.12/site-packages/asyncpg/connection.py", line 1925, in _do_execute
    stmt = await self._get_statement(
           ^^^^^^^^^^^^^^^^^^^^^^^^^^
  File "/root/miniconda3/lib/python3.12/site-packages/asyncpg/connection.py", line 433, in _get_statement
    statement = await self._protocol.prepare(
                ^^^^^^^^^^^^^^^^^^^^^^^^^^^^^
  File "asyncpg/protocol/protocol.pyx", line 166, in prepare
asyncpg.exceptions.UndefinedTableError: relation "imgonly" does not exist
[2024-08-13 05:19:12] [ERROR   ] discord.client: Ignoring exception in on_message
Traceback (most recent call last):
  File "/root/miniconda3/lib/python3.12/site-packages/discord/client.py", line 450, in _run_event
    await coro(*args, **kwargs)
  File "/root/AkariBot/events/messages.py", line 383, in imageonly_check
    if await self.bot.db.fetchrow(
       ^^^^^^^^^^^^^^^^^^^^^^^^^^^
  File "/root/miniconda3/lib/python3.12/site-packages/asyncpg/pool.py", line 601, in fetchrow
    return await con.fetchrow(
           ^^^^^^^^^^^^^^^^^^^
  File "/root/miniconda3/lib/python3.12/site-packages/asyncpg/connection.py", line 749, in fetchrow
    data = await self._execute(
           ^^^^^^^^^^^^^^^^^^^^
  File "/root/miniconda3/lib/python3.12/site-packages/asyncpg/connection.py", line 1794, in _execute
    result, _ = await self.__execute(
                ^^^^^^^^^^^^^^^^^^^^^
  File "/root/miniconda3/lib/python3.12/site-packages/asyncpg/connection.py", line 1892, in __execute
    result, stmt = await self._do_execute(
                   ^^^^^^^^^^^^^^^^^^^^^^^
  File "/root/miniconda3/lib/python3.12/site-packages/asyncpg/connection.py", line 1925, in _do_execute
    stmt = await self._get_statement(
           ^^^^^^^^^^^^^^^^^^^^^^^^^^
  File "/root/miniconda3/lib/python3.12/site-packages/asyncpg/connection.py", line 433, in _get_statement
    statement = await self._protocol.prepare(
                ^^^^^^^^^^^^^^^^^^^^^^^^^^^^^
  File "asyncpg/protocol/protocol.pyx", line 166, in prepare
asyncpg.exceptions.UndefinedTableError: relation "imgonly" does not exist
[2024-08-13 05:19:13] [ERROR   ] discord.client: Ignoring exception in on_message
Traceback (most recent call last):
  File "/root/miniconda3/lib/python3.12/site-packages/discord/client.py", line 450, in _run_event
    await coro(*args, **kwargs)
  File "/root/AkariBot/events/messages.py", line 383, in imageonly_check
    if await self.bot.db.fetchrow(
       ^^^^^^^^^^^^^^^^^^^^^^^^^^^
  File "/root/miniconda3/lib/python3.12/site-packages/asyncpg/pool.py", line 601, in fetchrow
    return await con.fetchrow(
           ^^^^^^^^^^^^^^^^^^^
  File "/root/miniconda3/lib/python3.12/site-packages/asyncpg/connection.py", line 749, in fetchrow
    data = await self._execute(
           ^^^^^^^^^^^^^^^^^^^^
  File "/root/miniconda3/lib/python3.12/site-packages/asyncpg/connection.py", line 1794, in _execute
    result, _ = await self.__execute(
                ^^^^^^^^^^^^^^^^^^^^^
  File "/root/miniconda3/lib/python3.12/site-packages/asyncpg/connection.py", line 1892, in __execute
    result, stmt = await self._do_execute(
                   ^^^^^^^^^^^^^^^^^^^^^^^
  File "/root/miniconda3/lib/python3.12/site-packages/asyncpg/connection.py", line 1925, in _do_execute
    stmt = await self._get_statement(
           ^^^^^^^^^^^^^^^^^^^^^^^^^^
  File "/root/miniconda3/lib/python3.12/site-packages/asyncpg/connection.py", line 433, in _get_statement
    statement = await self._protocol.prepare(
                ^^^^^^^^^^^^^^^^^^^^^^^^^^^^^
  File "asyncpg/protocol/protocol.pyx", line 166, in prepare
asyncpg.exceptions.UndefinedTableError: relation "imgonly" does not exist
[2024-08-13 05:19:13] [ERROR   ] discord.client: Ignoring exception in on_ready
Traceback (most recent call last):
  File "/root/miniconda3/lib/python3.12/site-packages/discord/client.py", line 450, in _run_event
    await coro(*args, **kwargs)
  File "/root/AkariBot/tools/bot.py", line 401, in on_ready
    await Music(self).start_nodes()
  File "/root/AkariBot/cogs/music.py", line 89, in start_nodes
    await self.pomice.create_node(
  File "/root/miniconda3/lib/python3.12/site-packages/pomice/pool.py", line 1046, in create_node
    await node.connect()
  File "/root/miniconda3/lib/python3.12/site-packages/pomice/pool.py", line 496, in connect
    raise NodeConnectionFailure(
pomice.exceptions.NodeConnectionFailure: The connection to node 'MAIN' failed.
[2024-08-13 05:19:14] [ERROR   ] discord.client: Ignoring exception in on_message
Traceback (most recent call last):
  File "/root/miniconda3/lib/python3.12/site-packages/discord/client.py", line 450, in _run_event
    await coro(*args, **kwargs)
  File "/root/AkariBot/events/messages.py", line 383, in imageonly_check
    if await self.bot.db.fetchrow(
       ^^^^^^^^^^^^^^^^^^^^^^^^^^^
  File "/root/miniconda3/lib/python3.12/site-packages/asyncpg/pool.py", line 601, in fetchrow
    return await con.fetchrow(
           ^^^^^^^^^^^^^^^^^^^
  File "/root/miniconda3/lib/python3.12/site-packages/asyncpg/connection.py", line 749, in fetchrow
    data = await self._execute(
           ^^^^^^^^^^^^^^^^^^^^
  File "/root/miniconda3/lib/python3.12/site-packages/asyncpg/connection.py", line 1794, in _execute
    result, _ = await self.__execute(
                ^^^^^^^^^^^^^^^^^^^^^
  File "/root/miniconda3/lib/python3.12/site-packages/asyncpg/connection.py", line 1892, in __execute
    result, stmt = await self._do_execute(
                   ^^^^^^^^^^^^^^^^^^^^^^^
  File "/root/miniconda3/lib/python3.12/site-packages/asyncpg/connection.py", line 1925, in _do_execute
    stmt = await self._get_statement(
           ^^^^^^^^^^^^^^^^^^^^^^^^^^
  File "/root/miniconda3/lib/python3.12/site-packages/asyncpg/connection.py", line 433, in _get_statement
    statement = await self._protocol.prepare(
                ^^^^^^^^^^^^^^^^^^^^^^^^^^^^^
  File "asyncpg/protocol/protocol.pyx", line 166, in prepare
asyncpg.exceptions.UndefinedTableError: relation "imgonly" does not exist
[2024-08-13 05:19:14] [ERROR   ] discord.client: Ignoring exception in on_message
Traceback (most recent call last):
  File "/root/miniconda3/lib/python3.12/site-packages/discord/client.py", line 450, in _run_event
    await coro(*args, **kwargs)
  File "/root/AkariBot/events/messages.py", line 383, in imageonly_check
    if await self.bot.db.fetchrow(
       ^^^^^^^^^^^^^^^^^^^^^^^^^^^
  File "/root/miniconda3/lib/python3.12/site-packages/asyncpg/pool.py", line 601, in fetchrow
    return await con.fetchrow(
           ^^^^^^^^^^^^^^^^^^^
  File "/root/miniconda3/lib/python3.12/site-packages/asyncpg/connection.py", line 749, in fetchrow
    data = await self._execute(
           ^^^^^^^^^^^^^^^^^^^^
  File "/root/miniconda3/lib/python3.12/site-packages/asyncpg/connection.py", line 1794, in _execute
    result, _ = await self.__execute(
                ^^^^^^^^^^^^^^^^^^^^^
  File "/root/miniconda3/lib/python3.12/site-packages/asyncpg/connection.py", line 1892, in __execute
    result, stmt = await self._do_execute(
                   ^^^^^^^^^^^^^^^^^^^^^^^
  File "/root/miniconda3/lib/python3.12/site-packages/asyncpg/connection.py", line 1925, in _do_execute
    stmt = await self._get_statement(
           ^^^^^^^^^^^^^^^^^^^^^^^^^^
  File "/root/miniconda3/lib/python3.12/site-packages/asyncpg/connection.py", line 433, in _get_statement
    statement = await self._protocol.prepare(
                ^^^^^^^^^^^^^^^^^^^^^^^^^^^^^
  File "asyncpg/protocol/protocol.pyx", line 166, in prepare
asyncpg.exceptions.UndefinedTableError: relation "imgonly" does not exist
[2024-08-13 05:19:15] [ERROR   ] discord.client: Ignoring exception in on_message
Traceback (most recent call last):
  File "/root/miniconda3/lib/python3.12/site-packages/discord/client.py", line 450, in _run_event
    await coro(*args, **kwargs)
  File "/root/AkariBot/events/messages.py", line 383, in imageonly_check
    if await self.bot.db.fetchrow(
       ^^^^^^^^^^^^^^^^^^^^^^^^^^^
  File "/root/miniconda3/lib/python3.12/site-packages/asyncpg/pool.py", line 601, in fetchrow
    return await con.fetchrow(
           ^^^^^^^^^^^^^^^^^^^
  File "/root/miniconda3/lib/python3.12/site-packages/asyncpg/connection.py", line 749, in fetchrow
    data = await self._execute(
           ^^^^^^^^^^^^^^^^^^^^
  File "/root/miniconda3/lib/python3.12/site-packages/asyncpg/connection.py", line 1794, in _execute
    result, _ = await self.__execute(
                ^^^^^^^^^^^^^^^^^^^^^
  File "/root/miniconda3/lib/python3.12/site-packages/asyncpg/connection.py", line 1892, in __execute
    result, stmt = await self._do_execute(
                   ^^^^^^^^^^^^^^^^^^^^^^^
  File "/root/miniconda3/lib/python3.12/site-packages/asyncpg/connection.py", line 1925, in _do_execute
    stmt = await self._get_statement(
           ^^^^^^^^^^^^^^^^^^^^^^^^^^
  File "/root/miniconda3/lib/python3.12/site-packages/asyncpg/connection.py", line 433, in _get_statement
    statement = await self._protocol.prepare(
                ^^^^^^^^^^^^^^^^^^^^^^^^^^^^^
  File "asyncpg/protocol/protocol.pyx", line 166, in prepare
asyncpg.exceptions.UndefinedTableError: relation "imgonly" does not exist
[2024-08-13 05:19:16] [ERROR   ] discord.client: Ignoring exception in on_message
Traceback (most recent call last):
  File "/root/miniconda3/lib/python3.12/site-packages/discord/client.py", line 450, in _run_event
    await coro(*args, **kwargs)
  File "/root/AkariBot/events/messages.py", line 383, in imageonly_check
    if await self.bot.db.fetchrow(
       ^^^^^^^^^^^^^^^^^^^^^^^^^^^
  File "/root/miniconda3/lib/python3.12/site-packages/asyncpg/pool.py", line 601, in fetchrow
    return await con.fetchrow(
           ^^^^^^^^^^^^^^^^^^^
  File "/root/miniconda3/lib/python3.12/site-packages/asyncpg/connection.py", line 749, in fetchrow
    data = await self._execute(
           ^^^^^^^^^^^^^^^^^^^^
  File "/root/miniconda3/lib/python3.12/site-packages/asyncpg/connection.py", line 1794, in _execute
    result, _ = await self.__execute(
                ^^^^^^^^^^^^^^^^^^^^^
  File "/root/miniconda3/lib/python3.12/site-packages/asyncpg/connection.py", line 1892, in __execute
    result, stmt = await self._do_execute(
                   ^^^^^^^^^^^^^^^^^^^^^^^
  File "/root/miniconda3/lib/python3.12/site-packages/asyncpg/connection.py", line 1925, in _do_execute
    stmt = await self._get_statement(
           ^^^^^^^^^^^^^^^^^^^^^^^^^^
  File "/root/miniconda3/lib/python3.12/site-packages/asyncpg/connection.py", line 433, in _get_statement
    statement = await self._protocol.prepare(
                ^^^^^^^^^^^^^^^^^^^^^^^^^^^^^
  File "asyncpg/protocol/protocol.pyx", line 166, in prepare
asyncpg.exceptions.UndefinedTableError: relation "imgonly" does not exist
[2024-08-13 05:19:17] [ERROR   ] discord.client: Ignoring exception in on_message
Traceback (most recent call last):
  File "/root/miniconda3/lib/python3.12/site-packages/discord/client.py", line 450, in _run_event
    await coro(*args, **kwargs)
  File "/root/AkariBot/events/messages.py", line 383, in imageonly_check
    if await self.bot.db.fetchrow(
       ^^^^^^^^^^^^^^^^^^^^^^^^^^^
  File "/root/miniconda3/lib/python3.12/site-packages/asyncpg/pool.py", line 601, in fetchrow
    return await con.fetchrow(
           ^^^^^^^^^^^^^^^^^^^
  File "/root/miniconda3/lib/python3.12/site-packages/asyncpg/connection.py", line 749, in fetchrow
    data = await self._execute(
           ^^^^^^^^^^^^^^^^^^^^
  File "/root/miniconda3/lib/python3.12/site-packages/asyncpg/connection.py", line 1794, in _execute
    result, _ = await self.__execute(
                ^^^^^^^^^^^^^^^^^^^^^
  File "/root/miniconda3/lib/python3.12/site-packages/asyncpg/connection.py", line 1892, in __execute
    result, stmt = await self._do_execute(
                   ^^^^^^^^^^^^^^^^^^^^^^^
  File "/root/miniconda3/lib/python3.12/site-packages/asyncpg/connection.py", line 1925, in _do_execute
    stmt = await self._get_statement(
           ^^^^^^^^^^^^^^^^^^^^^^^^^^
  File "/root/miniconda3/lib/python3.12/site-packages/asyncpg/connection.py", line 433, in _get_statement
    statement = await self._protocol.prepare(
                ^^^^^^^^^^^^^^^^^^^^^^^^^^^^^
  File "asyncpg/protocol/protocol.pyx", line 166, in prepare
asyncpg.exceptions.UndefinedTableError: relation "imgonly" does not exist
[2024-08-13 05:19:19] [ERROR   ] discord.client: Ignoring exception in on_message
Traceback (most recent call last):
  File "/root/miniconda3/lib/python3.12/site-packages/discord/client.py", line 450, in _run_event
    await coro(*args, **kwargs)
  File "/root/AkariBot/events/messages.py", line 383, in imageonly_check
    if await self.bot.db.fetchrow(
       ^^^^^^^^^^^^^^^^^^^^^^^^^^^
  File "/root/miniconda3/lib/python3.12/site-packages/asyncpg/pool.py", line 601, in fetchrow
    return await con.fetchrow(
           ^^^^^^^^^^^^^^^^^^^
  File "/root/miniconda3/lib/python3.12/site-packages/asyncpg/connection.py", line 749, in fetchrow
    data = await self._execute(
           ^^^^^^^^^^^^^^^^^^^^
  File "/root/miniconda3/lib/python3.12/site-packages/asyncpg/connection.py", line 1794, in _execute
    result, _ = await self.__execute(
                ^^^^^^^^^^^^^^^^^^^^^
  File "/root/miniconda3/lib/python3.12/site-packages/asyncpg/connection.py", line 1892, in __execute
    result, stmt = await self._do_execute(
                   ^^^^^^^^^^^^^^^^^^^^^^^
  File "/root/miniconda3/lib/python3.12/site-packages/asyncpg/connection.py", line 1925, in _do_execute
    stmt = await self._get_statement(
           ^^^^^^^^^^^^^^^^^^^^^^^^^^
  File "/root/miniconda3/lib/python3.12/site-packages/asyncpg/connection.py", line 433, in _get_statement
    statement = await self._protocol.prepare(
                ^^^^^^^^^^^^^^^^^^^^^^^^^^^^^
  File "asyncpg/protocol/protocol.pyx", line 166, in prepare
asyncpg.exceptions.UndefinedTableError: relation "imgonly" does not exist
[2024-08-13 05:19:22] [ERROR   ] discord.client: Ignoring exception in on_message
Traceback (most recent call last):
  File "/root/miniconda3/lib/python3.12/site-packages/discord/client.py", line 450, in _run_event
    await coro(*args, **kwargs)
  File "/root/AkariBot/events/messages.py", line 383, in imageonly_check
    if await self.bot.db.fetchrow(
       ^^^^^^^^^^^^^^^^^^^^^^^^^^^
  File "/root/miniconda3/lib/python3.12/site-packages/asyncpg/pool.py", line 601, in fetchrow
    return await con.fetchrow(
           ^^^^^^^^^^^^^^^^^^^
  File "/root/miniconda3/lib/python3.12/site-packages/asyncpg/connection.py", line 749, in fetchrow
    data = await self._execute(
           ^^^^^^^^^^^^^^^^^^^^
  File "/root/miniconda3/lib/python3.12/site-packages/asyncpg/connection.py", line 1794, in _execute
    result, _ = await self.__execute(
                ^^^^^^^^^^^^^^^^^^^^^
  File "/root/miniconda3/lib/python3.12/site-packages/asyncpg/connection.py", line 1892, in __execute
    result, stmt = await self._do_execute(
                   ^^^^^^^^^^^^^^^^^^^^^^^
  File "/root/miniconda3/lib/python3.12/site-packages/asyncpg/connection.py", line 1925, in _do_execute
    stmt = await self._get_statement(
           ^^^^^^^^^^^^^^^^^^^^^^^^^^
  File "/root/miniconda3/lib/python3.12/site-packages/asyncpg/connection.py", line 433, in _get_statement
    statement = await self._protocol.prepare(
                ^^^^^^^^^^^^^^^^^^^^^^^^^^^^^
  File "asyncpg/protocol/protocol.pyx", line 166, in prepare
asyncpg.exceptions.UndefinedTableError: relation "imgonly" does not exist
[2024-08-13 05:19:24] [ERROR   ] discord.client: Ignoring exception in on_message
Traceback (most recent call last):
  File "/root/miniconda3/lib/python3.12/site-packages/discord/client.py", line 450, in _run_event
    await coro(*args, **kwargs)
  File "/root/AkariBot/events/messages.py", line 383, in imageonly_check
    if await self.bot.db.fetchrow(
       ^^^^^^^^^^^^^^^^^^^^^^^^^^^
  File "/root/miniconda3/lib/python3.12/site-packages/asyncpg/pool.py", line 601, in fetchrow
    return await con.fetchrow(
           ^^^^^^^^^^^^^^^^^^^
  File "/root/miniconda3/lib/python3.12/site-packages/asyncpg/connection.py", line 749, in fetchrow
    data = await self._execute(
           ^^^^^^^^^^^^^^^^^^^^
  File "/root/miniconda3/lib/python3.12/site-packages/asyncpg/connection.py", line 1794, in _execute
    result, _ = await self.__execute(
                ^^^^^^^^^^^^^^^^^^^^^
  File "/root/miniconda3/lib/python3.12/site-packages/asyncpg/connection.py", line 1892, in __execute
    result, stmt = await self._do_execute(
                   ^^^^^^^^^^^^^^^^^^^^^^^
  File "/root/miniconda3/lib/python3.12/site-packages/asyncpg/connection.py", line 1925, in _do_execute
    stmt = await self._get_statement(
           ^^^^^^^^^^^^^^^^^^^^^^^^^^
  File "/root/miniconda3/lib/python3.12/site-packages/asyncpg/connection.py", line 433, in _get_statement
    statement = await self._protocol.prepare(
                ^^^^^^^^^^^^^^^^^^^^^^^^^^^^^
  File "asyncpg/protocol/protocol.pyx", line 166, in prepare
asyncpg.exceptions.UndefinedTableError: relation "imgonly" does not exist
[2024-08-13 05:19:25] [ERROR   ] discord.client: Ignoring exception in on_message
Traceback (most recent call last):
  File "/root/miniconda3/lib/python3.12/site-packages/discord/client.py", line 450, in _run_event
    await coro(*args, **kwargs)
  File "/root/AkariBot/events/messages.py", line 383, in imageonly_check
    if await self.bot.db.fetchrow(
       ^^^^^^^^^^^^^^^^^^^^^^^^^^^
  File "/root/miniconda3/lib/python3.12/site-packages/asyncpg/pool.py", line 601, in fetchrow
    return await con.fetchrow(
           ^^^^^^^^^^^^^^^^^^^
  File "/root/miniconda3/lib/python3.12/site-packages/asyncpg/connection.py", line 749, in fetchrow
    data = await self._execute(
           ^^^^^^^^^^^^^^^^^^^^
  File "/root/miniconda3/lib/python3.12/site-packages/asyncpg/connection.py", line 1794, in _execute
    result, _ = await self.__execute(
                ^^^^^^^^^^^^^^^^^^^^^
  File "/root/miniconda3/lib/python3.12/site-packages/asyncpg/connection.py", line 1892, in __execute
    result, stmt = await self._do_execute(
                   ^^^^^^^^^^^^^^^^^^^^^^^
  File "/root/miniconda3/lib/python3.12/site-packages/asyncpg/connection.py", line 1925, in _do_execute
    stmt = await self._get_statement(
           ^^^^^^^^^^^^^^^^^^^^^^^^^^
  File "/root/miniconda3/lib/python3.12/site-packages/asyncpg/connection.py", line 433, in _get_statement
    statement = await self._protocol.prepare(
                ^^^^^^^^^^^^^^^^^^^^^^^^^^^^^
  File "asyncpg/protocol/protocol.pyx", line 166, in prepare
asyncpg.exceptions.UndefinedTableError: relation "imgonly" does not exist
[2024-08-13 05:19:29] [ERROR   ] discord.client: Ignoring exception in on_message
Traceback (most recent call last):
  File "/root/miniconda3/lib/python3.12/site-packages/discord/client.py", line 450, in _run_event
    await coro(*args, **kwargs)
  File "/root/AkariBot/events/messages.py", line 383, in imageonly_check
    if await self.bot.db.fetchrow(
       ^^^^^^^^^^^^^^^^^^^^^^^^^^^
  File "/root/miniconda3/lib/python3.12/site-packages/asyncpg/pool.py", line 601, in fetchrow
    return await con.fetchrow(
           ^^^^^^^^^^^^^^^^^^^
  File "/root/miniconda3/lib/python3.12/site-packages/asyncpg/connection.py", line 749, in fetchrow
    data = await self._execute(
           ^^^^^^^^^^^^^^^^^^^^
  File "/root/miniconda3/lib/python3.12/site-packages/asyncpg/connection.py", line 1794, in _execute
    result, _ = await self.__execute(
                ^^^^^^^^^^^^^^^^^^^^^
  File "/root/miniconda3/lib/python3.12/site-packages/asyncpg/connection.py", line 1892, in __execute
    result, stmt = await self._do_execute(
                   ^^^^^^^^^^^^^^^^^^^^^^^
  File "/root/miniconda3/lib/python3.12/site-packages/asyncpg/connection.py", line 1925, in _do_execute
    stmt = await self._get_statement(
           ^^^^^^^^^^^^^^^^^^^^^^^^^^
  File "/root/miniconda3/lib/python3.12/site-packages/asyncpg/connection.py", line 433, in _get_statement
    statement = await self._protocol.prepare(
                ^^^^^^^^^^^^^^^^^^^^^^^^^^^^^
  File "asyncpg/protocol/protocol.pyx", line 166, in prepare
asyncpg.exceptions.UndefinedTableError: relation "imgonly" does not exist
[2024-08-13 05:19:30] [ERROR   ] discord.client: Ignoring exception in on_message
Traceback (most recent call last):
  File "/root/miniconda3/lib/python3.12/site-packages/discord/client.py", line 450, in _run_event
    await coro(*args, **kwargs)
  File "/root/AkariBot/events/messages.py", line 383, in imageonly_check
    if await self.bot.db.fetchrow(
       ^^^^^^^^^^^^^^^^^^^^^^^^^^^
  File "/root/miniconda3/lib/python3.12/site-packages/asyncpg/pool.py", line 601, in fetchrow
    return await con.fetchrow(
           ^^^^^^^^^^^^^^^^^^^
  File "/root/miniconda3/lib/python3.12/site-packages/asyncpg/connection.py", line 749, in fetchrow
    data = await self._execute(
           ^^^^^^^^^^^^^^^^^^^^
  File "/root/miniconda3/lib/python3.12/site-packages/asyncpg/connection.py", line 1794, in _execute
    result, _ = await self.__execute(
                ^^^^^^^^^^^^^^^^^^^^^
  File "/root/miniconda3/lib/python3.12/site-packages/asyncpg/connection.py", line 1892, in __execute
    result, stmt = await self._do_execute(
                   ^^^^^^^^^^^^^^^^^^^^^^^
  File "/root/miniconda3/lib/python3.12/site-packages/asyncpg/connection.py", line 1925, in _do_execute
    stmt = await self._get_statement(
           ^^^^^^^^^^^^^^^^^^^^^^^^^^
  File "/root/miniconda3/lib/python3.12/site-packages/asyncpg/connection.py", line 433, in _get_statement
    statement = await self._protocol.prepare(
                ^^^^^^^^^^^^^^^^^^^^^^^^^^^^^
  File "asyncpg/protocol/protocol.pyx", line 166, in prepare
asyncpg.exceptions.UndefinedTableError: relation "imgonly" does not exist
[2024-08-13 05:19:34] [ERROR   ] discord.client: Ignoring exception in on_message
Traceback (most recent call last):
  File "/root/miniconda3/lib/python3.12/site-packages/discord/client.py", line 450, in _run_event
    await coro(*args, **kwargs)
  File "/root/AkariBot/events/messages.py", line 383, in imageonly_check
    if await self.bot.db.fetchrow(
       ^^^^^^^^^^^^^^^^^^^^^^^^^^^
  File "/root/miniconda3/lib/python3.12/site-packages/asyncpg/pool.py", line 601, in fetchrow
    return await con.fetchrow(
           ^^^^^^^^^^^^^^^^^^^
  File "/root/miniconda3/lib/python3.12/site-packages/asyncpg/connection.py", line 749, in fetchrow
    data = await self._execute(
           ^^^^^^^^^^^^^^^^^^^^
  File "/root/miniconda3/lib/python3.12/site-packages/asyncpg/connection.py", line 1794, in _execute
    result, _ = await self.__execute(
                ^^^^^^^^^^^^^^^^^^^^^
  File "/root/miniconda3/lib/python3.12/site-packages/asyncpg/connection.py", line 1892, in __execute
    result, stmt = await self._do_execute(
                   ^^^^^^^^^^^^^^^^^^^^^^^
  File "/root/miniconda3/lib/python3.12/site-packages/asyncpg/connection.py", line 1925, in _do_execute
    stmt = await self._get_statement(
           ^^^^^^^^^^^^^^^^^^^^^^^^^^
  File "/root/miniconda3/lib/python3.12/site-packages/asyncpg/connection.py", line 433, in _get_statement
    statement = await self._protocol.prepare(
                ^^^^^^^^^^^^^^^^^^^^^^^^^^^^^
  File "asyncpg/protocol/protocol.pyx", line 166, in prepare
asyncpg.exceptions.UndefinedTableError: relation "imgonly" does not exist
[2024-08-13 05:19:35] [ERROR   ] discord.client: Ignoring exception in on_message
Traceback (most recent call last):
  File "/root/miniconda3/lib/python3.12/site-packages/discord/client.py", line 450, in _run_event
    await coro(*args, **kwargs)
  File "/root/AkariBot/events/messages.py", line 383, in imageonly_check
    if await self.bot.db.fetchrow(
       ^^^^^^^^^^^^^^^^^^^^^^^^^^^
  File "/root/miniconda3/lib/python3.12/site-packages/asyncpg/pool.py", line 601, in fetchrow
    return await con.fetchrow(
           ^^^^^^^^^^^^^^^^^^^
  File "/root/miniconda3/lib/python3.12/site-packages/asyncpg/connection.py", line 749, in fetchrow
    data = await self._execute(
           ^^^^^^^^^^^^^^^^^^^^
  File "/root/miniconda3/lib/python3.12/site-packages/asyncpg/connection.py", line 1794, in _execute
    result, _ = await self.__execute(
                ^^^^^^^^^^^^^^^^^^^^^
  File "/root/miniconda3/lib/python3.12/site-packages/asyncpg/connection.py", line 1892, in __execute
    result, stmt = await self._do_execute(
                   ^^^^^^^^^^^^^^^^^^^^^^^
  File "/root/miniconda3/lib/python3.12/site-packages/asyncpg/connection.py", line 1925, in _do_execute
    stmt = await self._get_statement(
           ^^^^^^^^^^^^^^^^^^^^^^^^^^
  File "/root/miniconda3/lib/python3.12/site-packages/asyncpg/connection.py", line 433, in _get_statement
    statement = await self._protocol.prepare(
                ^^^^^^^^^^^^^^^^^^^^^^^^^^^^^
  File "asyncpg/protocol/protocol.pyx", line 166, in prepare
asyncpg.exceptions.UndefinedTableError: relation "imgonly" does not exist
[2024-08-13 05:19:36] [ERROR   ] discord.client: Ignoring exception in on_message
Traceback (most recent call last):
  File "/root/miniconda3/lib/python3.12/site-packages/discord/client.py", line 450, in _run_event
    await coro(*args, **kwargs)
  File "/root/AkariBot/events/messages.py", line 383, in imageonly_check
    if await self.bot.db.fetchrow(
       ^^^^^^^^^^^^^^^^^^^^^^^^^^^
  File "/root/miniconda3/lib/python3.12/site-packages/asyncpg/pool.py", line 601, in fetchrow
    return await con.fetchrow(
           ^^^^^^^^^^^^^^^^^^^
  File "/root/miniconda3/lib/python3.12/site-packages/asyncpg/connection.py", line 749, in fetchrow
    data = await self._execute(
           ^^^^^^^^^^^^^^^^^^^^
  File "/root/miniconda3/lib/python3.12/site-packages/asyncpg/connection.py", line 1794, in _execute
    result, _ = await self.__execute(
                ^^^^^^^^^^^^^^^^^^^^^
  File "/root/miniconda3/lib/python3.12/site-packages/asyncpg/connection.py", line 1892, in __execute
    result, stmt = await self._do_execute(
                   ^^^^^^^^^^^^^^^^^^^^^^^
  File "/root/miniconda3/lib/python3.12/site-packages/asyncpg/connection.py", line 1925, in _do_execute
    stmt = await self._get_statement(
           ^^^^^^^^^^^^^^^^^^^^^^^^^^
  File "/root/miniconda3/lib/python3.12/site-packages/asyncpg/connection.py", line 433, in _get_statement
    statement = await self._protocol.prepare(
                ^^^^^^^^^^^^^^^^^^^^^^^^^^^^^
  File "asyncpg/protocol/protocol.pyx", line 166, in prepare
asyncpg.exceptions.UndefinedTableError: relation "imgonly" does not exist
[2024-08-13 05:19:36] [ERROR   ] discord.client: Ignoring exception in on_message
Traceback (most recent call last):
  File "/root/miniconda3/lib/python3.12/site-packages/discord/client.py", line 450, in _run_event
    await coro(*args, **kwargs)
  File "/root/AkariBot/events/messages.py", line 383, in imageonly_check
    if await self.bot.db.fetchrow(
       ^^^^^^^^^^^^^^^^^^^^^^^^^^^
  File "/root/miniconda3/lib/python3.12/site-packages/asyncpg/pool.py", line 601, in fetchrow
    return await con.fetchrow(
           ^^^^^^^^^^^^^^^^^^^
  File "/root/miniconda3/lib/python3.12/site-packages/asyncpg/connection.py", line 749, in fetchrow
    data = await self._execute(
           ^^^^^^^^^^^^^^^^^^^^
  File "/root/miniconda3/lib/python3.12/site-packages/asyncpg/connection.py", line 1794, in _execute
    result, _ = await self.__execute(
                ^^^^^^^^^^^^^^^^^^^^^
  File "/root/miniconda3/lib/python3.12/site-packages/asyncpg/connection.py", line 1892, in __execute
    result, stmt = await self._do_execute(
                   ^^^^^^^^^^^^^^^^^^^^^^^
  File "/root/miniconda3/lib/python3.12/site-packages/asyncpg/connection.py", line 1925, in _do_execute
    stmt = await self._get_statement(
           ^^^^^^^^^^^^^^^^^^^^^^^^^^
  File "/root/miniconda3/lib/python3.12/site-packages/asyncpg/connection.py", line 433, in _get_statement
    statement = await self._protocol.prepare(
                ^^^^^^^^^^^^^^^^^^^^^^^^^^^^^
  File "asyncpg/protocol/protocol.pyx", line 166, in prepare
asyncpg.exceptions.UndefinedTableError: relation "imgonly" does not exist
[2024-08-13 05:19:39] [ERROR   ] discord.client: Ignoring exception in on_message
Traceback (most recent call last):
  File "/root/miniconda3/lib/python3.12/site-packages/discord/client.py", line 450, in _run_event
    await coro(*args, **kwargs)
  File "/root/AkariBot/events/messages.py", line 383, in imageonly_check
    if await self.bot.db.fetchrow(
       ^^^^^^^^^^^^^^^^^^^^^^^^^^^
  File "/root/miniconda3/lib/python3.12/site-packages/asyncpg/pool.py", line 601, in fetchrow
    return await con.fetchrow(
           ^^^^^^^^^^^^^^^^^^^
  File "/root/miniconda3/lib/python3.12/site-packages/asyncpg/connection.py", line 749, in fetchrow
    data = await self._execute(
           ^^^^^^^^^^^^^^^^^^^^
  File "/root/miniconda3/lib/python3.12/site-packages/asyncpg/connection.py", line 1794, in _execute
    result, _ = await self.__execute(
                ^^^^^^^^^^^^^^^^^^^^^
  File "/root/miniconda3/lib/python3.12/site-packages/asyncpg/connection.py", line 1892, in __execute
    result, stmt = await self._do_execute(
                   ^^^^^^^^^^^^^^^^^^^^^^^
  File "/root/miniconda3/lib/python3.12/site-packages/asyncpg/connection.py", line 1925, in _do_execute
    stmt = await self._get_statement(
           ^^^^^^^^^^^^^^^^^^^^^^^^^^
  File "/root/miniconda3/lib/python3.12/site-packages/asyncpg/connection.py", line 433, in _get_statement
    statement = await self._protocol.prepare(
                ^^^^^^^^^^^^^^^^^^^^^^^^^^^^^
  File "asyncpg/protocol/protocol.pyx", line 166, in prepare
asyncpg.exceptions.UndefinedTableError: relation "imgonly" does not exist
[2024-08-13 05:19:40] [ERROR   ] discord.client: Ignoring exception in on_message
Traceback (most recent call last):
  File "/root/miniconda3/lib/python3.12/site-packages/discord/client.py", line 450, in _run_event
    await coro(*args, **kwargs)
  File "/root/AkariBot/events/messages.py", line 383, in imageonly_check
    if await self.bot.db.fetchrow(
       ^^^^^^^^^^^^^^^^^^^^^^^^^^^
  File "/root/miniconda3/lib/python3.12/site-packages/asyncpg/pool.py", line 601, in fetchrow
    return await con.fetchrow(
           ^^^^^^^^^^^^^^^^^^^
  File "/root/miniconda3/lib/python3.12/site-packages/asyncpg/connection.py", line 749, in fetchrow
    data = await self._execute(
           ^^^^^^^^^^^^^^^^^^^^
  File "/root/miniconda3/lib/python3.12/site-packages/asyncpg/connection.py", line 1794, in _execute
    result, _ = await self.__execute(
                ^^^^^^^^^^^^^^^^^^^^^
  File "/root/miniconda3/lib/python3.12/site-packages/asyncpg/connection.py", line 1892, in __execute
    result, stmt = await self._do_execute(
                   ^^^^^^^^^^^^^^^^^^^^^^^
  File "/root/miniconda3/lib/python3.12/site-packages/asyncpg/connection.py", line 1925, in _do_execute
    stmt = await self._get_statement(
           ^^^^^^^^^^^^^^^^^^^^^^^^^^
  File "/root/miniconda3/lib/python3.12/site-packages/asyncpg/connection.py", line 433, in _get_statement
    statement = await self._protocol.prepare(
                ^^^^^^^^^^^^^^^^^^^^^^^^^^^^^
  File "asyncpg/protocol/protocol.pyx", line 166, in prepare
asyncpg.exceptions.UndefinedTableError: relation "imgonly" does not exist
[2024-08-13 05:19:41] [ERROR   ] discord.client: Ignoring exception in on_message
Traceback (most recent call last):
  File "/root/miniconda3/lib/python3.12/site-packages/discord/client.py", line 450, in _run_event
    await coro(*args, **kwargs)
  File "/root/AkariBot/events/messages.py", line 383, in imageonly_check
    if await self.bot.db.fetchrow(
       ^^^^^^^^^^^^^^^^^^^^^^^^^^^
  File "/root/miniconda3/lib/python3.12/site-packages/asyncpg/pool.py", line 601, in fetchrow
    return await con.fetchrow(
           ^^^^^^^^^^^^^^^^^^^
  File "/root/miniconda3/lib/python3.12/site-packages/asyncpg/connection.py", line 749, in fetchrow
    data = await self._execute(
           ^^^^^^^^^^^^^^^^^^^^
  File "/root/miniconda3/lib/python3.12/site-packages/asyncpg/connection.py", line 1794, in _execute
    result, _ = await self.__execute(
                ^^^^^^^^^^^^^^^^^^^^^
  File "/root/miniconda3/lib/python3.12/site-packages/asyncpg/connection.py", line 1892, in __execute
    result, stmt = await self._do_execute(
                   ^^^^^^^^^^^^^^^^^^^^^^^
  File "/root/miniconda3/lib/python3.12/site-packages/asyncpg/connection.py", line 1925, in _do_execute
    stmt = await self._get_statement(
           ^^^^^^^^^^^^^^^^^^^^^^^^^^
  File "/root/miniconda3/lib/python3.12/site-packages/asyncpg/connection.py", line 433, in _get_statement
    statement = await self._protocol.prepare(
                ^^^^^^^^^^^^^^^^^^^^^^^^^^^^^
  File "asyncpg/protocol/protocol.pyx", line 166, in prepare
asyncpg.exceptions.UndefinedTableError: relation "imgonly" does not exist
[2024-08-13 05:19:42] [ERROR   ] discord.client: Ignoring exception in on_message
Traceback (most recent call last):
  File "/root/miniconda3/lib/python3.12/site-packages/discord/client.py", line 450, in _run_event
    await coro(*args, **kwargs)
  File "/root/AkariBot/events/messages.py", line 383, in imageonly_check
    if await self.bot.db.fetchrow(
       ^^^^^^^^^^^^^^^^^^^^^^^^^^^
  File "/root/miniconda3/lib/python3.12/site-packages/asyncpg/pool.py", line 601, in fetchrow
    return await con.fetchrow(
           ^^^^^^^^^^^^^^^^^^^
  File "/root/miniconda3/lib/python3.12/site-packages/asyncpg/connection.py", line 749, in fetchrow
    data = await self._execute(
           ^^^^^^^^^^^^^^^^^^^^
  File "/root/miniconda3/lib/python3.12/site-packages/asyncpg/connection.py", line 1794, in _execute
    result, _ = await self.__execute(
                ^^^^^^^^^^^^^^^^^^^^^
  File "/root/miniconda3/lib/python3.12/site-packages/asyncpg/connection.py", line 1892, in __execute
    result, stmt = await self._do_execute(
                   ^^^^^^^^^^^^^^^^^^^^^^^
  File "/root/miniconda3/lib/python3.12/site-packages/asyncpg/connection.py", line 1925, in _do_execute
    stmt = await self._get_statement(
           ^^^^^^^^^^^^^^^^^^^^^^^^^^
  File "/root/miniconda3/lib/python3.12/site-packages/asyncpg/connection.py", line 433, in _get_statement
    statement = await self._protocol.prepare(
                ^^^^^^^^^^^^^^^^^^^^^^^^^^^^^
  File "asyncpg/protocol/protocol.pyx", line 166, in prepare
asyncpg.exceptions.UndefinedTableError: relation "imgonly" does not exist
[2024-08-13 05:19:42] [ERROR   ] discord.client: Ignoring exception in on_message
Traceback (most recent call last):
  File "/root/miniconda3/lib/python3.12/site-packages/discord/client.py", line 450, in _run_event
    await coro(*args, **kwargs)
  File "/root/AkariBot/events/messages.py", line 383, in imageonly_check
    if await self.bot.db.fetchrow(
       ^^^^^^^^^^^^^^^^^^^^^^^^^^^
  File "/root/miniconda3/lib/python3.12/site-packages/asyncpg/pool.py", line 601, in fetchrow
    return await con.fetchrow(
           ^^^^^^^^^^^^^^^^^^^
  File "/root/miniconda3/lib/python3.12/site-packages/asyncpg/connection.py", line 749, in fetchrow
    data = await self._execute(
           ^^^^^^^^^^^^^^^^^^^^
  File "/root/miniconda3/lib/python3.12/site-packages/asyncpg/connection.py", line 1794, in _execute
    result, _ = await self.__execute(
                ^^^^^^^^^^^^^^^^^^^^^
  File "/root/miniconda3/lib/python3.12/site-packages/asyncpg/connection.py", line 1892, in __execute
    result, stmt = await self._do_execute(
                   ^^^^^^^^^^^^^^^^^^^^^^^
  File "/root/miniconda3/lib/python3.12/site-packages/asyncpg/connection.py", line 1925, in _do_execute
    stmt = await self._get_statement(
           ^^^^^^^^^^^^^^^^^^^^^^^^^^
  File "/root/miniconda3/lib/python3.12/site-packages/asyncpg/connection.py", line 433, in _get_statement
    statement = await self._protocol.prepare(
                ^^^^^^^^^^^^^^^^^^^^^^^^^^^^^
  File "asyncpg/protocol/protocol.pyx", line 166, in prepare
asyncpg.exceptions.UndefinedTableError: relation "imgonly" does not exist
[2024-08-13 05:19:45] [ERROR   ] discord.client: Ignoring exception in on_message
Traceback (most recent call last):
  File "/root/miniconda3/lib/python3.12/site-packages/discord/client.py", line 450, in _run_event
    await coro(*args, **kwargs)
  File "/root/AkariBot/events/messages.py", line 383, in imageonly_check
    if await self.bot.db.fetchrow(
       ^^^^^^^^^^^^^^^^^^^^^^^^^^^
  File "/root/miniconda3/lib/python3.12/site-packages/asyncpg/pool.py", line 601, in fetchrow
    return await con.fetchrow(
           ^^^^^^^^^^^^^^^^^^^
  File "/root/miniconda3/lib/python3.12/site-packages/asyncpg/connection.py", line 749, in fetchrow
    data = await self._execute(
           ^^^^^^^^^^^^^^^^^^^^
  File "/root/miniconda3/lib/python3.12/site-packages/asyncpg/connection.py", line 1794, in _execute
    result, _ = await self.__execute(
                ^^^^^^^^^^^^^^^^^^^^^
  File "/root/miniconda3/lib/python3.12/site-packages/asyncpg/connection.py", line 1892, in __execute
    result, stmt = await self._do_execute(
                   ^^^^^^^^^^^^^^^^^^^^^^^
  File "/root/miniconda3/lib/python3.12/site-packages/asyncpg/connection.py", line 1925, in _do_execute
    stmt = await self._get_statement(
           ^^^^^^^^^^^^^^^^^^^^^^^^^^
  File "/root/miniconda3/lib/python3.12/site-packages/asyncpg/connection.py", line 433, in _get_statement
    statement = await self._protocol.prepare(
                ^^^^^^^^^^^^^^^^^^^^^^^^^^^^^
  File "asyncpg/protocol/protocol.pyx", line 166, in prepare
asyncpg.exceptions.UndefinedTableError: relation "imgonly" does not exist
[2024-08-13 05:19:45] [ERROR   ] discord.client: Ignoring exception in on_message
Traceback (most recent call last):
  File "/root/miniconda3/lib/python3.12/site-packages/discord/client.py", line 450, in _run_event
    await coro(*args, **kwargs)
  File "/root/AkariBot/events/messages.py", line 383, in imageonly_check
    if await self.bot.db.fetchrow(
       ^^^^^^^^^^^^^^^^^^^^^^^^^^^
  File "/root/miniconda3/lib/python3.12/site-packages/asyncpg/pool.py", line 601, in fetchrow
    return await con.fetchrow(
           ^^^^^^^^^^^^^^^^^^^
  File "/root/miniconda3/lib/python3.12/site-packages/asyncpg/connection.py", line 749, in fetchrow
    data = await self._execute(
           ^^^^^^^^^^^^^^^^^^^^
  File "/root/miniconda3/lib/python3.12/site-packages/asyncpg/connection.py", line 1794, in _execute
    result, _ = await self.__execute(
                ^^^^^^^^^^^^^^^^^^^^^
  File "/root/miniconda3/lib/python3.12/site-packages/asyncpg/connection.py", line 1892, in __execute
    result, stmt = await self._do_execute(
                   ^^^^^^^^^^^^^^^^^^^^^^^
  File "/root/miniconda3/lib/python3.12/site-packages/asyncpg/connection.py", line 1925, in _do_execute
    stmt = await self._get_statement(
           ^^^^^^^^^^^^^^^^^^^^^^^^^^
  File "/root/miniconda3/lib/python3.12/site-packages/asyncpg/connection.py", line 433, in _get_statement
    statement = await self._protocol.prepare(
                ^^^^^^^^^^^^^^^^^^^^^^^^^^^^^
  File "asyncpg/protocol/protocol.pyx", line 166, in prepare
asyncpg.exceptions.UndefinedTableError: relation "imgonly" does not exist
[2024-08-13 05:19:45] [ERROR   ] discord.client: Ignoring exception in on_message
Traceback (most recent call last):
  File "/root/miniconda3/lib/python3.12/site-packages/discord/client.py", line 450, in _run_event
    await coro(*args, **kwargs)
  File "/root/AkariBot/events/messages.py", line 383, in imageonly_check
    if await self.bot.db.fetchrow(
       ^^^^^^^^^^^^^^^^^^^^^^^^^^^
  File "/root/miniconda3/lib/python3.12/site-packages/asyncpg/pool.py", line 601, in fetchrow
    return await con.fetchrow(
           ^^^^^^^^^^^^^^^^^^^
  File "/root/miniconda3/lib/python3.12/site-packages/asyncpg/connection.py", line 749, in fetchrow
    data = await self._execute(
           ^^^^^^^^^^^^^^^^^^^^
  File "/root/miniconda3/lib/python3.12/site-packages/asyncpg/connection.py", line 1794, in _execute
    result, _ = await self.__execute(
                ^^^^^^^^^^^^^^^^^^^^^
  File "/root/miniconda3/lib/python3.12/site-packages/asyncpg/connection.py", line 1892, in __execute
    result, stmt = await self._do_execute(
                   ^^^^^^^^^^^^^^^^^^^^^^^
  File "/root/miniconda3/lib/python3.12/site-packages/asyncpg/connection.py", line 1925, in _do_execute
    stmt = await self._get_statement(
           ^^^^^^^^^^^^^^^^^^^^^^^^^^
  File "/root/miniconda3/lib/python3.12/site-packages/asyncpg/connection.py", line 433, in _get_statement
    statement = await self._protocol.prepare(
                ^^^^^^^^^^^^^^^^^^^^^^^^^^^^^
  File "asyncpg/protocol/protocol.pyx", line 166, in prepare
asyncpg.exceptions.UndefinedTableError: relation "imgonly" does not exist
[2024-08-13 05:19:46] [ERROR   ] discord.client: Ignoring exception in on_message
Traceback (most recent call last):
  File "/root/miniconda3/lib/python3.12/site-packages/discord/client.py", line 450, in _run_event
    await coro(*args, **kwargs)
  File "/root/AkariBot/events/messages.py", line 383, in imageonly_check
    if await self.bot.db.fetchrow(
       ^^^^^^^^^^^^^^^^^^^^^^^^^^^
  File "/root/miniconda3/lib/python3.12/site-packages/asyncpg/pool.py", line 601, in fetchrow
    return await con.fetchrow(
           ^^^^^^^^^^^^^^^^^^^
  File "/root/miniconda3/lib/python3.12/site-packages/asyncpg/connection.py", line 749, in fetchrow
    data = await self._execute(
           ^^^^^^^^^^^^^^^^^^^^
  File "/root/miniconda3/lib/python3.12/site-packages/asyncpg/connection.py", line 1794, in _execute
    result, _ = await self.__execute(
                ^^^^^^^^^^^^^^^^^^^^^
  File "/root/miniconda3/lib/python3.12/site-packages/asyncpg/connection.py", line 1892, in __execute
    result, stmt = await self._do_execute(
                   ^^^^^^^^^^^^^^^^^^^^^^^
  File "/root/miniconda3/lib/python3.12/site-packages/asyncpg/connection.py", line 1925, in _do_execute
    stmt = await self._get_statement(
           ^^^^^^^^^^^^^^^^^^^^^^^^^^
  File "/root/miniconda3/lib/python3.12/site-packages/asyncpg/connection.py", line 433, in _get_statement
    statement = await self._protocol.prepare(
                ^^^^^^^^^^^^^^^^^^^^^^^^^^^^^
  File "asyncpg/protocol/protocol.pyx", line 166, in prepare
asyncpg.exceptions.UndefinedTableError: relation "imgonly" does not exist
[2024-08-13 05:19:47] [ERROR   ] discord.client: Ignoring exception in on_message
Traceback (most recent call last):
  File "/root/miniconda3/lib/python3.12/site-packages/discord/client.py", line 450, in _run_event
    await coro(*args, **kwargs)
  File "/root/AkariBot/events/messages.py", line 383, in imageonly_check
    if await self.bot.db.fetchrow(
       ^^^^^^^^^^^^^^^^^^^^^^^^^^^
  File "/root/miniconda3/lib/python3.12/site-packages/asyncpg/pool.py", line 601, in fetchrow
    return await con.fetchrow(
           ^^^^^^^^^^^^^^^^^^^
  File "/root/miniconda3/lib/python3.12/site-packages/asyncpg/connection.py", line 749, in fetchrow
    data = await self._execute(
           ^^^^^^^^^^^^^^^^^^^^
  File "/root/miniconda3/lib/python3.12/site-packages/asyncpg/connection.py", line 1794, in _execute
    result, _ = await self.__execute(
                ^^^^^^^^^^^^^^^^^^^^^
  File "/root/miniconda3/lib/python3.12/site-packages/asyncpg/connection.py", line 1892, in __execute
    result, stmt = await self._do_execute(
                   ^^^^^^^^^^^^^^^^^^^^^^^
  File "/root/miniconda3/lib/python3.12/site-packages/asyncpg/connection.py", line 1925, in _do_execute
    stmt = await self._get_statement(
           ^^^^^^^^^^^^^^^^^^^^^^^^^^
  File "/root/miniconda3/lib/python3.12/site-packages/asyncpg/connection.py", line 433, in _get_statement
    statement = await self._protocol.prepare(
                ^^^^^^^^^^^^^^^^^^^^^^^^^^^^^
  File "asyncpg/protocol/protocol.pyx", line 166, in prepare
asyncpg.exceptions.UndefinedTableError: relation "imgonly" does not exist
[2024-08-13 05:19:50] [ERROR   ] discord.client: Ignoring exception in on_message
Traceback (most recent call last):
  File "/root/miniconda3/lib/python3.12/site-packages/discord/client.py", line 450, in _run_event
    await coro(*args, **kwargs)
  File "/root/AkariBot/events/messages.py", line 383, in imageonly_check
    if await self.bot.db.fetchrow(
       ^^^^^^^^^^^^^^^^^^^^^^^^^^^
  File "/root/miniconda3/lib/python3.12/site-packages/asyncpg/pool.py", line 601, in fetchrow
    return await con.fetchrow(
           ^^^^^^^^^^^^^^^^^^^
  File "/root/miniconda3/lib/python3.12/site-packages/asyncpg/connection.py", line 749, in fetchrow
    data = await self._execute(
           ^^^^^^^^^^^^^^^^^^^^
  File "/root/miniconda3/lib/python3.12/site-packages/asyncpg/connection.py", line 1794, in _execute
    result, _ = await self.__execute(
                ^^^^^^^^^^^^^^^^^^^^^
  File "/root/miniconda3/lib/python3.12/site-packages/asyncpg/connection.py", line 1892, in __execute
    result, stmt = await self._do_execute(
                   ^^^^^^^^^^^^^^^^^^^^^^^
  File "/root/miniconda3/lib/python3.12/site-packages/asyncpg/connection.py", line 1925, in _do_execute
    stmt = await self._get_statement(
           ^^^^^^^^^^^^^^^^^^^^^^^^^^
  File "/root/miniconda3/lib/python3.12/site-packages/asyncpg/connection.py", line 433, in _get_statement
    statement = await self._protocol.prepare(
                ^^^^^^^^^^^^^^^^^^^^^^^^^^^^^
  File "asyncpg/protocol/protocol.pyx", line 166, in prepare
asyncpg.exceptions.UndefinedTableError: relation "imgonly" does not exist
[2024-08-13 05:19:54] [ERROR   ] discord.client: Ignoring exception in on_message
Traceback (most recent call last):
  File "/root/miniconda3/lib/python3.12/site-packages/discord/client.py", line 450, in _run_event
    await coro(*args, **kwargs)
  File "/root/AkariBot/events/messages.py", line 383, in imageonly_check
    if await self.bot.db.fetchrow(
       ^^^^^^^^^^^^^^^^^^^^^^^^^^^
  File "/root/miniconda3/lib/python3.12/site-packages/asyncpg/pool.py", line 601, in fetchrow
    return await con.fetchrow(
           ^^^^^^^^^^^^^^^^^^^
  File "/root/miniconda3/lib/python3.12/site-packages/asyncpg/connection.py", line 749, in fetchrow
    data = await self._execute(
           ^^^^^^^^^^^^^^^^^^^^
  File "/root/miniconda3/lib/python3.12/site-packages/asyncpg/connection.py", line 1794, in _execute
    result, _ = await self.__execute(
                ^^^^^^^^^^^^^^^^^^^^^
  File "/root/miniconda3/lib/python3.12/site-packages/asyncpg/connection.py", line 1892, in __execute
    result, stmt = await self._do_execute(
                   ^^^^^^^^^^^^^^^^^^^^^^^
  File "/root/miniconda3/lib/python3.12/site-packages/asyncpg/connection.py", line 1925, in _do_execute
    stmt = await self._get_statement(
           ^^^^^^^^^^^^^^^^^^^^^^^^^^
  File "/root/miniconda3/lib/python3.12/site-packages/asyncpg/connection.py", line 433, in _get_statement
    statement = await self._protocol.prepare(
                ^^^^^^^^^^^^^^^^^^^^^^^^^^^^^
  File "asyncpg/protocol/protocol.pyx", line 166, in prepare
asyncpg.exceptions.UndefinedTableError: relation "imgonly" does not exist
[2024-08-13 05:19:57] [ERROR   ] discord.client: Ignoring exception in on_message
Traceback (most recent call last):
  File "/root/miniconda3/lib/python3.12/site-packages/discord/client.py", line 450, in _run_event
    await coro(*args, **kwargs)
  File "/root/AkariBot/events/messages.py", line 383, in imageonly_check
    if await self.bot.db.fetchrow(
       ^^^^^^^^^^^^^^^^^^^^^^^^^^^
  File "/root/miniconda3/lib/python3.12/site-packages/asyncpg/pool.py", line 601, in fetchrow
    return await con.fetchrow(
           ^^^^^^^^^^^^^^^^^^^
  File "/root/miniconda3/lib/python3.12/site-packages/asyncpg/connection.py", line 749, in fetchrow
    data = await self._execute(
           ^^^^^^^^^^^^^^^^^^^^
  File "/root/miniconda3/lib/python3.12/site-packages/asyncpg/connection.py", line 1794, in _execute
    result, _ = await self.__execute(
                ^^^^^^^^^^^^^^^^^^^^^
  File "/root/miniconda3/lib/python3.12/site-packages/asyncpg/connection.py", line 1892, in __execute
    result, stmt = await self._do_execute(
                   ^^^^^^^^^^^^^^^^^^^^^^^
  File "/root/miniconda3/lib/python3.12/site-packages/asyncpg/connection.py", line 1925, in _do_execute
    stmt = await self._get_statement(
           ^^^^^^^^^^^^^^^^^^^^^^^^^^
  File "/root/miniconda3/lib/python3.12/site-packages/asyncpg/connection.py", line 433, in _get_statement
    statement = await self._protocol.prepare(
                ^^^^^^^^^^^^^^^^^^^^^^^^^^^^^
  File "asyncpg/protocol/protocol.pyx", line 166, in prepare
asyncpg.exceptions.UndefinedTableError: relation "imgonly" does not exist
[2024-08-13 05:20:01] [ERROR   ] discord.client: Ignoring exception in on_message
Traceback (most recent call last):
  File "/root/miniconda3/lib/python3.12/site-packages/discord/client.py", line 450, in _run_event
    await coro(*args, **kwargs)
  File "/root/AkariBot/events/messages.py", line 383, in imageonly_check
    if await self.bot.db.fetchrow(
       ^^^^^^^^^^^^^^^^^^^^^^^^^^^
  File "/root/miniconda3/lib/python3.12/site-packages/asyncpg/pool.py", line 601, in fetchrow
    return await con.fetchrow(
           ^^^^^^^^^^^^^^^^^^^
  File "/root/miniconda3/lib/python3.12/site-packages/asyncpg/connection.py", line 749, in fetchrow
    data = await self._execute(
           ^^^^^^^^^^^^^^^^^^^^
  File "/root/miniconda3/lib/python3.12/site-packages/asyncpg/connection.py", line 1794, in _execute
    result, _ = await self.__execute(
                ^^^^^^^^^^^^^^^^^^^^^
  File "/root/miniconda3/lib/python3.12/site-packages/asyncpg/connection.py", line 1892, in __execute
    result, stmt = await self._do_execute(
                   ^^^^^^^^^^^^^^^^^^^^^^^
  File "/root/miniconda3/lib/python3.12/site-packages/asyncpg/connection.py", line 1925, in _do_execute
    stmt = await self._get_statement(
           ^^^^^^^^^^^^^^^^^^^^^^^^^^
  File "/root/miniconda3/lib/python3.12/site-packages/asyncpg/connection.py", line 433, in _get_statement
    statement = await self._protocol.prepare(
                ^^^^^^^^^^^^^^^^^^^^^^^^^^^^^
  File "asyncpg/protocol/protocol.pyx", line 166, in prepare
asyncpg.exceptions.UndefinedTableError: relation "imgonly" does not exist
[2024-08-13 05:20:02] [ERROR   ] discord.client: Ignoring exception in on_message
Traceback (most recent call last):
  File "/root/miniconda3/lib/python3.12/site-packages/discord/client.py", line 450, in _run_event
    await coro(*args, **kwargs)
  File "/root/AkariBot/events/messages.py", line 383, in imageonly_check
    if await self.bot.db.fetchrow(
       ^^^^^^^^^^^^^^^^^^^^^^^^^^^
  File "/root/miniconda3/lib/python3.12/site-packages/asyncpg/pool.py", line 601, in fetchrow
    return await con.fetchrow(
           ^^^^^^^^^^^^^^^^^^^
  File "/root/miniconda3/lib/python3.12/site-packages/asyncpg/connection.py", line 749, in fetchrow
    data = await self._execute(
           ^^^^^^^^^^^^^^^^^^^^
  File "/root/miniconda3/lib/python3.12/site-packages/asyncpg/connection.py", line 1794, in _execute
    result, _ = await self.__execute(
                ^^^^^^^^^^^^^^^^^^^^^
  File "/root/miniconda3/lib/python3.12/site-packages/asyncpg/connection.py", line 1892, in __execute
    result, stmt = await self._do_execute(
                   ^^^^^^^^^^^^^^^^^^^^^^^
  File "/root/miniconda3/lib/python3.12/site-packages/asyncpg/connection.py", line 1925, in _do_execute
    stmt = await self._get_statement(
           ^^^^^^^^^^^^^^^^^^^^^^^^^^
  File "/root/miniconda3/lib/python3.12/site-packages/asyncpg/connection.py", line 433, in _get_statement
    statement = await self._protocol.prepare(
                ^^^^^^^^^^^^^^^^^^^^^^^^^^^^^
  File "asyncpg/protocol/protocol.pyx", line 166, in prepare
asyncpg.exceptions.UndefinedTableError: relation "imgonly" does not exist
[2024-08-13 05:20:03] [ERROR   ] discord.client: Ignoring exception in on_message
Traceback (most recent call last):
  File "/root/miniconda3/lib/python3.12/site-packages/discord/client.py", line 450, in _run_event
    await coro(*args, **kwargs)
  File "/root/AkariBot/events/messages.py", line 383, in imageonly_check
    if await self.bot.db.fetchrow(
       ^^^^^^^^^^^^^^^^^^^^^^^^^^^
  File "/root/miniconda3/lib/python3.12/site-packages/asyncpg/pool.py", line 601, in fetchrow
    return await con.fetchrow(
           ^^^^^^^^^^^^^^^^^^^
  File "/root/miniconda3/lib/python3.12/site-packages/asyncpg/connection.py", line 749, in fetchrow
    data = await self._execute(
           ^^^^^^^^^^^^^^^^^^^^
  File "/root/miniconda3/lib/python3.12/site-packages/asyncpg/connection.py", line 1794, in _execute
    result, _ = await self.__execute(
                ^^^^^^^^^^^^^^^^^^^^^
  File "/root/miniconda3/lib/python3.12/site-packages/asyncpg/connection.py", line 1892, in __execute
    result, stmt = await self._do_execute(
                   ^^^^^^^^^^^^^^^^^^^^^^^
  File "/root/miniconda3/lib/python3.12/site-packages/asyncpg/connection.py", line 1925, in _do_execute
    stmt = await self._get_statement(
           ^^^^^^^^^^^^^^^^^^^^^^^^^^
  File "/root/miniconda3/lib/python3.12/site-packages/asyncpg/connection.py", line 433, in _get_statement
    statement = await self._protocol.prepare(
                ^^^^^^^^^^^^^^^^^^^^^^^^^^^^^
  File "asyncpg/protocol/protocol.pyx", line 166, in prepare
asyncpg.exceptions.UndefinedTableError: relation "imgonly" does not exist
[2024-08-13 05:20:03] [ERROR   ] discord.client: Ignoring exception in on_message
Traceback (most recent call last):
  File "/root/miniconda3/lib/python3.12/site-packages/discord/client.py", line 450, in _run_event
    await coro(*args, **kwargs)
  File "/root/AkariBot/events/messages.py", line 383, in imageonly_check
    if await self.bot.db.fetchrow(
       ^^^^^^^^^^^^^^^^^^^^^^^^^^^
  File "/root/miniconda3/lib/python3.12/site-packages/asyncpg/pool.py", line 601, in fetchrow
    return await con.fetchrow(
           ^^^^^^^^^^^^^^^^^^^
  File "/root/miniconda3/lib/python3.12/site-packages/asyncpg/connection.py", line 749, in fetchrow
    data = await self._execute(
           ^^^^^^^^^^^^^^^^^^^^
  File "/root/miniconda3/lib/python3.12/site-packages/asyncpg/connection.py", line 1794, in _execute
    result, _ = await self.__execute(
                ^^^^^^^^^^^^^^^^^^^^^
  File "/root/miniconda3/lib/python3.12/site-packages/asyncpg/connection.py", line 1892, in __execute
    result, stmt = await self._do_execute(
                   ^^^^^^^^^^^^^^^^^^^^^^^
  File "/root/miniconda3/lib/python3.12/site-packages/asyncpg/connection.py", line 1925, in _do_execute
    stmt = await self._get_statement(
           ^^^^^^^^^^^^^^^^^^^^^^^^^^
  File "/root/miniconda3/lib/python3.12/site-packages/asyncpg/connection.py", line 433, in _get_statement
    statement = await self._protocol.prepare(
                ^^^^^^^^^^^^^^^^^^^^^^^^^^^^^
  File "asyncpg/protocol/protocol.pyx", line 166, in prepare
asyncpg.exceptions.UndefinedTableError: relation "imgonly" does not exist
[2024-08-13 05:20:04] [ERROR   ] discord.client: Ignoring exception in on_message
Traceback (most recent call last):
  File "/root/miniconda3/lib/python3.12/site-packages/discord/client.py", line 450, in _run_event
    await coro(*args, **kwargs)
  File "/root/AkariBot/events/messages.py", line 383, in imageonly_check
    if await self.bot.db.fetchrow(
       ^^^^^^^^^^^^^^^^^^^^^^^^^^^
  File "/root/miniconda3/lib/python3.12/site-packages/asyncpg/pool.py", line 601, in fetchrow
    return await con.fetchrow(
           ^^^^^^^^^^^^^^^^^^^
  File "/root/miniconda3/lib/python3.12/site-packages/asyncpg/connection.py", line 749, in fetchrow
    data = await self._execute(
           ^^^^^^^^^^^^^^^^^^^^
  File "/root/miniconda3/lib/python3.12/site-packages/asyncpg/connection.py", line 1794, in _execute
    result, _ = await self.__execute(
                ^^^^^^^^^^^^^^^^^^^^^
  File "/root/miniconda3/lib/python3.12/site-packages/asyncpg/connection.py", line 1892, in __execute
    result, stmt = await self._do_execute(
                   ^^^^^^^^^^^^^^^^^^^^^^^
  File "/root/miniconda3/lib/python3.12/site-packages/asyncpg/connection.py", line 1925, in _do_execute
    stmt = await self._get_statement(
           ^^^^^^^^^^^^^^^^^^^^^^^^^^
  File "/root/miniconda3/lib/python3.12/site-packages/asyncpg/connection.py", line 433, in _get_statement
    statement = await self._protocol.prepare(
                ^^^^^^^^^^^^^^^^^^^^^^^^^^^^^
  File "asyncpg/protocol/protocol.pyx", line 166, in prepare
asyncpg.exceptions.UndefinedTableError: relation "imgonly" does not exist
[2024-08-13 05:20:09] [ERROR   ] discord.client: Ignoring exception in on_message
Traceback (most recent call last):
  File "/root/miniconda3/lib/python3.12/site-packages/discord/client.py", line 450, in _run_event
    await coro(*args, **kwargs)
  File "/root/AkariBot/events/messages.py", line 383, in imageonly_check
    if await self.bot.db.fetchrow(
       ^^^^^^^^^^^^^^^^^^^^^^^^^^^
  File "/root/miniconda3/lib/python3.12/site-packages/asyncpg/pool.py", line 601, in fetchrow
    return await con.fetchrow(
           ^^^^^^^^^^^^^^^^^^^
  File "/root/miniconda3/lib/python3.12/site-packages/asyncpg/connection.py", line 749, in fetchrow
    data = await self._execute(
           ^^^^^^^^^^^^^^^^^^^^
  File "/root/miniconda3/lib/python3.12/site-packages/asyncpg/connection.py", line 1794, in _execute
    result, _ = await self.__execute(
                ^^^^^^^^^^^^^^^^^^^^^
  File "/root/miniconda3/lib/python3.12/site-packages/asyncpg/connection.py", line 1892, in __execute
    result, stmt = await self._do_execute(
                   ^^^^^^^^^^^^^^^^^^^^^^^
  File "/root/miniconda3/lib/python3.12/site-packages/asyncpg/connection.py", line 1925, in _do_execute
    stmt = await self._get_statement(
           ^^^^^^^^^^^^^^^^^^^^^^^^^^
  File "/root/miniconda3/lib/python3.12/site-packages/asyncpg/connection.py", line 433, in _get_statement
    statement = await self._protocol.prepare(
                ^^^^^^^^^^^^^^^^^^^^^^^^^^^^^
  File "asyncpg/protocol/protocol.pyx", line 166, in prepare
asyncpg.exceptions.UndefinedTableError: relation "imgonly" does not exist
[2024-08-13 05:20:10] [ERROR   ] discord.client: Ignoring exception in on_message
Traceback (most recent call last):
  File "/root/miniconda3/lib/python3.12/site-packages/discord/client.py", line 450, in _run_event
    await coro(*args, **kwargs)
  File "/root/AkariBot/events/messages.py", line 383, in imageonly_check
    if await self.bot.db.fetchrow(
       ^^^^^^^^^^^^^^^^^^^^^^^^^^^
  File "/root/miniconda3/lib/python3.12/site-packages/asyncpg/pool.py", line 601, in fetchrow
    return await con.fetchrow(
           ^^^^^^^^^^^^^^^^^^^
  File "/root/miniconda3/lib/python3.12/site-packages/asyncpg/connection.py", line 749, in fetchrow
    data = await self._execute(
           ^^^^^^^^^^^^^^^^^^^^
  File "/root/miniconda3/lib/python3.12/site-packages/asyncpg/connection.py", line 1794, in _execute
    result, _ = await self.__execute(
                ^^^^^^^^^^^^^^^^^^^^^
  File "/root/miniconda3/lib/python3.12/site-packages/asyncpg/connection.py", line 1892, in __execute
    result, stmt = await self._do_execute(
                   ^^^^^^^^^^^^^^^^^^^^^^^
  File "/root/miniconda3/lib/python3.12/site-packages/asyncpg/connection.py", line 1925, in _do_execute
    stmt = await self._get_statement(
           ^^^^^^^^^^^^^^^^^^^^^^^^^^
  File "/root/miniconda3/lib/python3.12/site-packages/asyncpg/connection.py", line 433, in _get_statement
    statement = await self._protocol.prepare(
                ^^^^^^^^^^^^^^^^^^^^^^^^^^^^^
  File "asyncpg/protocol/protocol.pyx", line 166, in prepare
asyncpg.exceptions.UndefinedTableError: relation "imgonly" does not exist
[2024-08-13 05:20:14] [ERROR   ] discord.client: Ignoring exception in on_message
Traceback (most recent call last):
  File "/root/miniconda3/lib/python3.12/site-packages/discord/client.py", line 450, in _run_event
    await coro(*args, **kwargs)
  File "/root/AkariBot/events/messages.py", line 383, in imageonly_check
    if await self.bot.db.fetchrow(
       ^^^^^^^^^^^^^^^^^^^^^^^^^^^
  File "/root/miniconda3/lib/python3.12/site-packages/asyncpg/pool.py", line 601, in fetchrow
    return await con.fetchrow(
           ^^^^^^^^^^^^^^^^^^^
  File "/root/miniconda3/lib/python3.12/site-packages/asyncpg/connection.py", line 749, in fetchrow
    data = await self._execute(
           ^^^^^^^^^^^^^^^^^^^^
  File "/root/miniconda3/lib/python3.12/site-packages/asyncpg/connection.py", line 1794, in _execute
    result, _ = await self.__execute(
                ^^^^^^^^^^^^^^^^^^^^^
  File "/root/miniconda3/lib/python3.12/site-packages/asyncpg/connection.py", line 1892, in __execute
    result, stmt = await self._do_execute(
                   ^^^^^^^^^^^^^^^^^^^^^^^
  File "/root/miniconda3/lib/python3.12/site-packages/asyncpg/connection.py", line 1925, in _do_execute
    stmt = await self._get_statement(
           ^^^^^^^^^^^^^^^^^^^^^^^^^^
  File "/root/miniconda3/lib/python3.12/site-packages/asyncpg/connection.py", line 433, in _get_statement
    statement = await self._protocol.prepare(
                ^^^^^^^^^^^^^^^^^^^^^^^^^^^^^
  File "asyncpg/protocol/protocol.pyx", line 166, in prepare
asyncpg.exceptions.UndefinedTableError: relation "imgonly" does not exist
[2024-08-13 05:20:15] [ERROR   ] discord.client: Ignoring exception in on_message
Traceback (most recent call last):
  File "/root/miniconda3/lib/python3.12/site-packages/discord/client.py", line 450, in _run_event
    await coro(*args, **kwargs)
  File "/root/AkariBot/events/messages.py", line 383, in imageonly_check
    if await self.bot.db.fetchrow(
       ^^^^^^^^^^^^^^^^^^^^^^^^^^^
  File "/root/miniconda3/lib/python3.12/site-packages/asyncpg/pool.py", line 601, in fetchrow
    return await con.fetchrow(
           ^^^^^^^^^^^^^^^^^^^
  File "/root/miniconda3/lib/python3.12/site-packages/asyncpg/connection.py", line 749, in fetchrow
    data = await self._execute(
           ^^^^^^^^^^^^^^^^^^^^
  File "/root/miniconda3/lib/python3.12/site-packages/asyncpg/connection.py", line 1794, in _execute
    result, _ = await self.__execute(
                ^^^^^^^^^^^^^^^^^^^^^
  File "/root/miniconda3/lib/python3.12/site-packages/asyncpg/connection.py", line 1892, in __execute
    result, stmt = await self._do_execute(
                   ^^^^^^^^^^^^^^^^^^^^^^^
  File "/root/miniconda3/lib/python3.12/site-packages/asyncpg/connection.py", line 1925, in _do_execute
    stmt = await self._get_statement(
           ^^^^^^^^^^^^^^^^^^^^^^^^^^
  File "/root/miniconda3/lib/python3.12/site-packages/asyncpg/connection.py", line 433, in _get_statement
    statement = await self._protocol.prepare(
                ^^^^^^^^^^^^^^^^^^^^^^^^^^^^^
  File "asyncpg/protocol/protocol.pyx", line 166, in prepare
asyncpg.exceptions.UndefinedTableError: relation "imgonly" does not exist
[2024-08-13 05:20:17] [ERROR   ] discord.client: Ignoring exception in on_message
Traceback (most recent call last):
  File "/root/miniconda3/lib/python3.12/site-packages/discord/client.py", line 450, in _run_event
    await coro(*args, **kwargs)
  File "/root/AkariBot/events/messages.py", line 383, in imageonly_check
    if await self.bot.db.fetchrow(
       ^^^^^^^^^^^^^^^^^^^^^^^^^^^
  File "/root/miniconda3/lib/python3.12/site-packages/asyncpg/pool.py", line 601, in fetchrow
    return await con.fetchrow(
           ^^^^^^^^^^^^^^^^^^^
  File "/root/miniconda3/lib/python3.12/site-packages/asyncpg/connection.py", line 749, in fetchrow
    data = await self._execute(
           ^^^^^^^^^^^^^^^^^^^^
  File "/root/miniconda3/lib/python3.12/site-packages/asyncpg/connection.py", line 1794, in _execute
    result, _ = await self.__execute(
                ^^^^^^^^^^^^^^^^^^^^^
  File "/root/miniconda3/lib/python3.12/site-packages/asyncpg/connection.py", line 1892, in __execute
    result, stmt = await self._do_execute(
                   ^^^^^^^^^^^^^^^^^^^^^^^
  File "/root/miniconda3/lib/python3.12/site-packages/asyncpg/connection.py", line 1925, in _do_execute
    stmt = await self._get_statement(
           ^^^^^^^^^^^^^^^^^^^^^^^^^^
  File "/root/miniconda3/lib/python3.12/site-packages/asyncpg/connection.py", line 433, in _get_statement
    statement = await self._protocol.prepare(
                ^^^^^^^^^^^^^^^^^^^^^^^^^^^^^
  File "asyncpg/protocol/protocol.pyx", line 166, in prepare
asyncpg.exceptions.UndefinedTableError: relation "imgonly" does not exist
[2024-08-13 05:20:19] [ERROR   ] discord.client: Ignoring exception in on_message
Traceback (most recent call last):
  File "/root/miniconda3/lib/python3.12/site-packages/discord/client.py", line 450, in _run_event
    await coro(*args, **kwargs)
  File "/root/AkariBot/events/messages.py", line 383, in imageonly_check
    if await self.bot.db.fetchrow(
       ^^^^^^^^^^^^^^^^^^^^^^^^^^^
  File "/root/miniconda3/lib/python3.12/site-packages/asyncpg/pool.py", line 601, in fetchrow
    return await con.fetchrow(
           ^^^^^^^^^^^^^^^^^^^
  File "/root/miniconda3/lib/python3.12/site-packages/asyncpg/connection.py", line 749, in fetchrow
    data = await self._execute(
           ^^^^^^^^^^^^^^^^^^^^
  File "/root/miniconda3/lib/python3.12/site-packages/asyncpg/connection.py", line 1794, in _execute
    result, _ = await self.__execute(
                ^^^^^^^^^^^^^^^^^^^^^
  File "/root/miniconda3/lib/python3.12/site-packages/asyncpg/connection.py", line 1892, in __execute
    result, stmt = await self._do_execute(
                   ^^^^^^^^^^^^^^^^^^^^^^^
  File "/root/miniconda3/lib/python3.12/site-packages/asyncpg/connection.py", line 1925, in _do_execute
    stmt = await self._get_statement(
           ^^^^^^^^^^^^^^^^^^^^^^^^^^
  File "/root/miniconda3/lib/python3.12/site-packages/asyncpg/connection.py", line 433, in _get_statement
    statement = await self._protocol.prepare(
                ^^^^^^^^^^^^^^^^^^^^^^^^^^^^^
  File "asyncpg/protocol/protocol.pyx", line 166, in prepare
asyncpg.exceptions.UndefinedTableError: relation "imgonly" does not exist
[2024-08-13 05:20:20] [ERROR   ] discord.client: Ignoring exception in on_message
Traceback (most recent call last):
  File "/root/miniconda3/lib/python3.12/site-packages/discord/client.py", line 450, in _run_event
    await coro(*args, **kwargs)
  File "/root/AkariBot/events/messages.py", line 383, in imageonly_check
    if await self.bot.db.fetchrow(
       ^^^^^^^^^^^^^^^^^^^^^^^^^^^
  File "/root/miniconda3/lib/python3.12/site-packages/asyncpg/pool.py", line 601, in fetchrow
    return await con.fetchrow(
           ^^^^^^^^^^^^^^^^^^^
  File "/root/miniconda3/lib/python3.12/site-packages/asyncpg/connection.py", line 749, in fetchrow
    data = await self._execute(
           ^^^^^^^^^^^^^^^^^^^^
  File "/root/miniconda3/lib/python3.12/site-packages/asyncpg/connection.py", line 1794, in _execute
    result, _ = await self.__execute(
                ^^^^^^^^^^^^^^^^^^^^^
  File "/root/miniconda3/lib/python3.12/site-packages/asyncpg/connection.py", line 1892, in __execute
    result, stmt = await self._do_execute(
                   ^^^^^^^^^^^^^^^^^^^^^^^
  File "/root/miniconda3/lib/python3.12/site-packages/asyncpg/connection.py", line 1925, in _do_execute
    stmt = await self._get_statement(
           ^^^^^^^^^^^^^^^^^^^^^^^^^^
  File "/root/miniconda3/lib/python3.12/site-packages/asyncpg/connection.py", line 433, in _get_statement
    statement = await self._protocol.prepare(
                ^^^^^^^^^^^^^^^^^^^^^^^^^^^^^
  File "asyncpg/protocol/protocol.pyx", line 166, in prepare
asyncpg.exceptions.UndefinedTableError: relation "imgonly" does not exist
[2024-08-13 05:20:20] [ERROR   ] discord.client: Ignoring exception in on_message
Traceback (most recent call last):
  File "/root/miniconda3/lib/python3.12/site-packages/discord/client.py", line 450, in _run_event
    await coro(*args, **kwargs)
  File "/root/AkariBot/events/messages.py", line 383, in imageonly_check
    if await self.bot.db.fetchrow(
       ^^^^^^^^^^^^^^^^^^^^^^^^^^^
  File "/root/miniconda3/lib/python3.12/site-packages/asyncpg/pool.py", line 601, in fetchrow
    return await con.fetchrow(
           ^^^^^^^^^^^^^^^^^^^
  File "/root/miniconda3/lib/python3.12/site-packages/asyncpg/connection.py", line 749, in fetchrow
    data = await self._execute(
           ^^^^^^^^^^^^^^^^^^^^
  File "/root/miniconda3/lib/python3.12/site-packages/asyncpg/connection.py", line 1794, in _execute
    result, _ = await self.__execute(
                ^^^^^^^^^^^^^^^^^^^^^
  File "/root/miniconda3/lib/python3.12/site-packages/asyncpg/connection.py", line 1892, in __execute
    result, stmt = await self._do_execute(
                   ^^^^^^^^^^^^^^^^^^^^^^^
  File "/root/miniconda3/lib/python3.12/site-packages/asyncpg/connection.py", line 1925, in _do_execute
    stmt = await self._get_statement(
           ^^^^^^^^^^^^^^^^^^^^^^^^^^
  File "/root/miniconda3/lib/python3.12/site-packages/asyncpg/connection.py", line 433, in _get_statement
    statement = await self._protocol.prepare(
                ^^^^^^^^^^^^^^^^^^^^^^^^^^^^^
  File "asyncpg/protocol/protocol.pyx", line 166, in prepare
asyncpg.exceptions.UndefinedTableError: relation "imgonly" does not exist
[2024-08-13 05:20:24] [ERROR   ] discord.client: Ignoring exception in on_message
Traceback (most recent call last):
  File "/root/miniconda3/lib/python3.12/site-packages/discord/client.py", line 450, in _run_event
    await coro(*args, **kwargs)
  File "/root/AkariBot/events/messages.py", line 383, in imageonly_check
    if await self.bot.db.fetchrow(
       ^^^^^^^^^^^^^^^^^^^^^^^^^^^
  File "/root/miniconda3/lib/python3.12/site-packages/asyncpg/pool.py", line 601, in fetchrow
    return await con.fetchrow(
           ^^^^^^^^^^^^^^^^^^^
  File "/root/miniconda3/lib/python3.12/site-packages/asyncpg/connection.py", line 749, in fetchrow
    data = await self._execute(
           ^^^^^^^^^^^^^^^^^^^^
  File "/root/miniconda3/lib/python3.12/site-packages/asyncpg/connection.py", line 1794, in _execute
    result, _ = await self.__execute(
                ^^^^^^^^^^^^^^^^^^^^^
  File "/root/miniconda3/lib/python3.12/site-packages/asyncpg/connection.py", line 1892, in __execute
    result, stmt = await self._do_execute(
                   ^^^^^^^^^^^^^^^^^^^^^^^
  File "/root/miniconda3/lib/python3.12/site-packages/asyncpg/connection.py", line 1925, in _do_execute
    stmt = await self._get_statement(
           ^^^^^^^^^^^^^^^^^^^^^^^^^^
  File "/root/miniconda3/lib/python3.12/site-packages/asyncpg/connection.py", line 433, in _get_statement
    statement = await self._protocol.prepare(
                ^^^^^^^^^^^^^^^^^^^^^^^^^^^^^
  File "asyncpg/protocol/protocol.pyx", line 166, in prepare
asyncpg.exceptions.UndefinedTableError: relation "imgonly" does not exist
[2024-08-13 05:20:26] [ERROR   ] discord.client: Ignoring exception in on_message
Traceback (most recent call last):
  File "/root/miniconda3/lib/python3.12/site-packages/discord/client.py", line 450, in _run_event
    await coro(*args, **kwargs)
  File "/root/AkariBot/events/messages.py", line 383, in imageonly_check
    if await self.bot.db.fetchrow(
       ^^^^^^^^^^^^^^^^^^^^^^^^^^^
  File "/root/miniconda3/lib/python3.12/site-packages/asyncpg/pool.py", line 601, in fetchrow
    return await con.fetchrow(
           ^^^^^^^^^^^^^^^^^^^
  File "/root/miniconda3/lib/python3.12/site-packages/asyncpg/connection.py", line 749, in fetchrow
    data = await self._execute(
           ^^^^^^^^^^^^^^^^^^^^
  File "/root/miniconda3/lib/python3.12/site-packages/asyncpg/connection.py", line 1794, in _execute
    result, _ = await self.__execute(
                ^^^^^^^^^^^^^^^^^^^^^
  File "/root/miniconda3/lib/python3.12/site-packages/asyncpg/connection.py", line 1892, in __execute
    result, stmt = await self._do_execute(
                   ^^^^^^^^^^^^^^^^^^^^^^^
  File "/root/miniconda3/lib/python3.12/site-packages/asyncpg/connection.py", line 1925, in _do_execute
    stmt = await self._get_statement(
           ^^^^^^^^^^^^^^^^^^^^^^^^^^
  File "/root/miniconda3/lib/python3.12/site-packages/asyncpg/connection.py", line 433, in _get_statement
    statement = await self._protocol.prepare(
                ^^^^^^^^^^^^^^^^^^^^^^^^^^^^^
  File "asyncpg/protocol/protocol.pyx", line 166, in prepare
asyncpg.exceptions.UndefinedTableError: relation "imgonly" does not exist
[2024-08-13 05:20:27] [ERROR   ] discord.client: Ignoring exception in on_message
Traceback (most recent call last):
  File "/root/miniconda3/lib/python3.12/site-packages/discord/client.py", line 450, in _run_event
    await coro(*args, **kwargs)
  File "/root/AkariBot/events/messages.py", line 383, in imageonly_check
    if await self.bot.db.fetchrow(
       ^^^^^^^^^^^^^^^^^^^^^^^^^^^
  File "/root/miniconda3/lib/python3.12/site-packages/asyncpg/pool.py", line 601, in fetchrow
    return await con.fetchrow(
           ^^^^^^^^^^^^^^^^^^^
  File "/root/miniconda3/lib/python3.12/site-packages/asyncpg/connection.py", line 749, in fetchrow
    data = await self._execute(
           ^^^^^^^^^^^^^^^^^^^^
  File "/root/miniconda3/lib/python3.12/site-packages/asyncpg/connection.py", line 1794, in _execute
    result, _ = await self.__execute(
                ^^^^^^^^^^^^^^^^^^^^^
  File "/root/miniconda3/lib/python3.12/site-packages/asyncpg/connection.py", line 1892, in __execute
    result, stmt = await self._do_execute(
                   ^^^^^^^^^^^^^^^^^^^^^^^
  File "/root/miniconda3/lib/python3.12/site-packages/asyncpg/connection.py", line 1925, in _do_execute
    stmt = await self._get_statement(
           ^^^^^^^^^^^^^^^^^^^^^^^^^^
  File "/root/miniconda3/lib/python3.12/site-packages/asyncpg/connection.py", line 433, in _get_statement
    statement = await self._protocol.prepare(
                ^^^^^^^^^^^^^^^^^^^^^^^^^^^^^
  File "asyncpg/protocol/protocol.pyx", line 166, in prepare
asyncpg.exceptions.UndefinedTableError: relation "imgonly" does not exist
[2024-08-13 05:20:27] [ERROR   ] discord.client: Ignoring exception in on_message
Traceback (most recent call last):
  File "/root/miniconda3/lib/python3.12/site-packages/discord/client.py", line 450, in _run_event
    await coro(*args, **kwargs)
  File "/root/AkariBot/events/messages.py", line 383, in imageonly_check
    if await self.bot.db.fetchrow(
       ^^^^^^^^^^^^^^^^^^^^^^^^^^^
  File "/root/miniconda3/lib/python3.12/site-packages/asyncpg/pool.py", line 601, in fetchrow
    return await con.fetchrow(
           ^^^^^^^^^^^^^^^^^^^
  File "/root/miniconda3/lib/python3.12/site-packages/asyncpg/connection.py", line 749, in fetchrow
    data = await self._execute(
           ^^^^^^^^^^^^^^^^^^^^
  File "/root/miniconda3/lib/python3.12/site-packages/asyncpg/connection.py", line 1794, in _execute
    result, _ = await self.__execute(
                ^^^^^^^^^^^^^^^^^^^^^
  File "/root/miniconda3/lib/python3.12/site-packages/asyncpg/connection.py", line 1892, in __execute
    result, stmt = await self._do_execute(
                   ^^^^^^^^^^^^^^^^^^^^^^^
  File "/root/miniconda3/lib/python3.12/site-packages/asyncpg/connection.py", line 1925, in _do_execute
    stmt = await self._get_statement(
           ^^^^^^^^^^^^^^^^^^^^^^^^^^
  File "/root/miniconda3/lib/python3.12/site-packages/asyncpg/connection.py", line 433, in _get_statement
    statement = await self._protocol.prepare(
                ^^^^^^^^^^^^^^^^^^^^^^^^^^^^^
  File "asyncpg/protocol/protocol.pyx", line 166, in prepare
asyncpg.exceptions.UndefinedTableError: relation "imgonly" does not exist
[2024-08-13 05:20:28] [ERROR   ] discord.client: Ignoring exception in on_message
Traceback (most recent call last):
  File "/root/miniconda3/lib/python3.12/site-packages/discord/client.py", line 450, in _run_event
    await coro(*args, **kwargs)
  File "/root/AkariBot/events/messages.py", line 383, in imageonly_check
    if await self.bot.db.fetchrow(
       ^^^^^^^^^^^^^^^^^^^^^^^^^^^
  File "/root/miniconda3/lib/python3.12/site-packages/asyncpg/pool.py", line 601, in fetchrow
    return await con.fetchrow(
           ^^^^^^^^^^^^^^^^^^^
  File "/root/miniconda3/lib/python3.12/site-packages/asyncpg/connection.py", line 749, in fetchrow
    data = await self._execute(
           ^^^^^^^^^^^^^^^^^^^^
  File "/root/miniconda3/lib/python3.12/site-packages/asyncpg/connection.py", line 1794, in _execute
    result, _ = await self.__execute(
                ^^^^^^^^^^^^^^^^^^^^^
  File "/root/miniconda3/lib/python3.12/site-packages/asyncpg/connection.py", line 1892, in __execute
    result, stmt = await self._do_execute(
                   ^^^^^^^^^^^^^^^^^^^^^^^
  File "/root/miniconda3/lib/python3.12/site-packages/asyncpg/connection.py", line 1925, in _do_execute
    stmt = await self._get_statement(
           ^^^^^^^^^^^^^^^^^^^^^^^^^^
  File "/root/miniconda3/lib/python3.12/site-packages/asyncpg/connection.py", line 433, in _get_statement
    statement = await self._protocol.prepare(
                ^^^^^^^^^^^^^^^^^^^^^^^^^^^^^
  File "asyncpg/protocol/protocol.pyx", line 166, in prepare
asyncpg.exceptions.UndefinedTableError: relation "imgonly" does not exist
[2024-08-13 05:20:29] [ERROR   ] discord.client: Ignoring exception in on_message
Traceback (most recent call last):
  File "/root/miniconda3/lib/python3.12/site-packages/discord/client.py", line 450, in _run_event
    await coro(*args, **kwargs)
  File "/root/AkariBot/events/messages.py", line 383, in imageonly_check
    if await self.bot.db.fetchrow(
       ^^^^^^^^^^^^^^^^^^^^^^^^^^^
  File "/root/miniconda3/lib/python3.12/site-packages/asyncpg/pool.py", line 601, in fetchrow
    return await con.fetchrow(
           ^^^^^^^^^^^^^^^^^^^
  File "/root/miniconda3/lib/python3.12/site-packages/asyncpg/connection.py", line 749, in fetchrow
    data = await self._execute(
           ^^^^^^^^^^^^^^^^^^^^
  File "/root/miniconda3/lib/python3.12/site-packages/asyncpg/connection.py", line 1794, in _execute
    result, _ = await self.__execute(
                ^^^^^^^^^^^^^^^^^^^^^
  File "/root/miniconda3/lib/python3.12/site-packages/asyncpg/connection.py", line 1892, in __execute
    result, stmt = await self._do_execute(
                   ^^^^^^^^^^^^^^^^^^^^^^^
  File "/root/miniconda3/lib/python3.12/site-packages/asyncpg/connection.py", line 1925, in _do_execute
    stmt = await self._get_statement(
           ^^^^^^^^^^^^^^^^^^^^^^^^^^
  File "/root/miniconda3/lib/python3.12/site-packages/asyncpg/connection.py", line 433, in _get_statement
    statement = await self._protocol.prepare(
                ^^^^^^^^^^^^^^^^^^^^^^^^^^^^^
  File "asyncpg/protocol/protocol.pyx", line 166, in prepare
asyncpg.exceptions.UndefinedTableError: relation "imgonly" does not exist
[2024-08-13 05:20:29] [ERROR   ] discord.client: Ignoring exception in on_message
Traceback (most recent call last):
  File "/root/miniconda3/lib/python3.12/site-packages/discord/client.py", line 450, in _run_event
    await coro(*args, **kwargs)
  File "/root/AkariBot/events/messages.py", line 383, in imageonly_check
    if await self.bot.db.fetchrow(
       ^^^^^^^^^^^^^^^^^^^^^^^^^^^
  File "/root/miniconda3/lib/python3.12/site-packages/asyncpg/pool.py", line 601, in fetchrow
    return await con.fetchrow(
           ^^^^^^^^^^^^^^^^^^^
  File "/root/miniconda3/lib/python3.12/site-packages/asyncpg/connection.py", line 749, in fetchrow
    data = await self._execute(
           ^^^^^^^^^^^^^^^^^^^^
  File "/root/miniconda3/lib/python3.12/site-packages/asyncpg/connection.py", line 1794, in _execute
    result, _ = await self.__execute(
                ^^^^^^^^^^^^^^^^^^^^^
  File "/root/miniconda3/lib/python3.12/site-packages/asyncpg/connection.py", line 1892, in __execute
    result, stmt = await self._do_execute(
                   ^^^^^^^^^^^^^^^^^^^^^^^
  File "/root/miniconda3/lib/python3.12/site-packages/asyncpg/connection.py", line 1925, in _do_execute
    stmt = await self._get_statement(
           ^^^^^^^^^^^^^^^^^^^^^^^^^^
  File "/root/miniconda3/lib/python3.12/site-packages/asyncpg/connection.py", line 433, in _get_statement
    statement = await self._protocol.prepare(
                ^^^^^^^^^^^^^^^^^^^^^^^^^^^^^
  File "asyncpg/protocol/protocol.pyx", line 166, in prepare
asyncpg.exceptions.UndefinedTableError: relation "imgonly" does not exist
[2024-08-13 05:20:29] [ERROR   ] discord.client: Ignoring exception in on_message
Traceback (most recent call last):
  File "/root/miniconda3/lib/python3.12/site-packages/discord/client.py", line 450, in _run_event
    await coro(*args, **kwargs)
  File "/root/AkariBot/events/messages.py", line 383, in imageonly_check
    if await self.bot.db.fetchrow(
       ^^^^^^^^^^^^^^^^^^^^^^^^^^^
  File "/root/miniconda3/lib/python3.12/site-packages/asyncpg/pool.py", line 601, in fetchrow
    return await con.fetchrow(
           ^^^^^^^^^^^^^^^^^^^
  File "/root/miniconda3/lib/python3.12/site-packages/asyncpg/connection.py", line 749, in fetchrow
    data = await self._execute(
           ^^^^^^^^^^^^^^^^^^^^
  File "/root/miniconda3/lib/python3.12/site-packages/asyncpg/connection.py", line 1794, in _execute
    result, _ = await self.__execute(
                ^^^^^^^^^^^^^^^^^^^^^
  File "/root/miniconda3/lib/python3.12/site-packages/asyncpg/connection.py", line 1892, in __execute
    result, stmt = await self._do_execute(
                   ^^^^^^^^^^^^^^^^^^^^^^^
  File "/root/miniconda3/lib/python3.12/site-packages/asyncpg/connection.py", line 1925, in _do_execute
    stmt = await self._get_statement(
           ^^^^^^^^^^^^^^^^^^^^^^^^^^
  File "/root/miniconda3/lib/python3.12/site-packages/asyncpg/connection.py", line 433, in _get_statement
    statement = await self._protocol.prepare(
                ^^^^^^^^^^^^^^^^^^^^^^^^^^^^^
  File "asyncpg/protocol/protocol.pyx", line 166, in prepare
asyncpg.exceptions.UndefinedTableError: relation "imgonly" does not exist
[2024-08-13 05:20:36] [ERROR   ] discord.client: Ignoring exception in on_message
Traceback (most recent call last):
  File "/root/miniconda3/lib/python3.12/site-packages/discord/client.py", line 450, in _run_event
    await coro(*args, **kwargs)
  File "/root/AkariBot/events/messages.py", line 383, in imageonly_check
    if await self.bot.db.fetchrow(
       ^^^^^^^^^^^^^^^^^^^^^^^^^^^
  File "/root/miniconda3/lib/python3.12/site-packages/asyncpg/pool.py", line 601, in fetchrow
    return await con.fetchrow(
           ^^^^^^^^^^^^^^^^^^^
  File "/root/miniconda3/lib/python3.12/site-packages/asyncpg/connection.py", line 749, in fetchrow
    data = await self._execute(
           ^^^^^^^^^^^^^^^^^^^^
  File "/root/miniconda3/lib/python3.12/site-packages/asyncpg/connection.py", line 1794, in _execute
    result, _ = await self.__execute(
                ^^^^^^^^^^^^^^^^^^^^^
  File "/root/miniconda3/lib/python3.12/site-packages/asyncpg/connection.py", line 1892, in __execute
    result, stmt = await self._do_execute(
                   ^^^^^^^^^^^^^^^^^^^^^^^
  File "/root/miniconda3/lib/python3.12/site-packages/asyncpg/connection.py", line 1925, in _do_execute
    stmt = await self._get_statement(
           ^^^^^^^^^^^^^^^^^^^^^^^^^^
  File "/root/miniconda3/lib/python3.12/site-packages/asyncpg/connection.py", line 433, in _get_statement
    statement = await self._protocol.prepare(
                ^^^^^^^^^^^^^^^^^^^^^^^^^^^^^
  File "asyncpg/protocol/protocol.pyx", line 166, in prepare
asyncpg.exceptions.UndefinedTableError: relation "imgonly" does not exist
[2024-08-13 05:20:36] [ERROR   ] discord.client: Ignoring exception in on_message
Traceback (most recent call last):
  File "/root/miniconda3/lib/python3.12/site-packages/discord/client.py", line 450, in _run_event
    await coro(*args, **kwargs)
  File "/root/AkariBot/events/messages.py", line 383, in imageonly_check
    if await self.bot.db.fetchrow(
       ^^^^^^^^^^^^^^^^^^^^^^^^^^^
  File "/root/miniconda3/lib/python3.12/site-packages/asyncpg/pool.py", line 601, in fetchrow
    return await con.fetchrow(
           ^^^^^^^^^^^^^^^^^^^
  File "/root/miniconda3/lib/python3.12/site-packages/asyncpg/connection.py", line 749, in fetchrow
    data = await self._execute(
           ^^^^^^^^^^^^^^^^^^^^
  File "/root/miniconda3/lib/python3.12/site-packages/asyncpg/connection.py", line 1794, in _execute
    result, _ = await self.__execute(
                ^^^^^^^^^^^^^^^^^^^^^
  File "/root/miniconda3/lib/python3.12/site-packages/asyncpg/connection.py", line 1892, in __execute
    result, stmt = await self._do_execute(
                   ^^^^^^^^^^^^^^^^^^^^^^^
  File "/root/miniconda3/lib/python3.12/site-packages/asyncpg/connection.py", line 1925, in _do_execute
    stmt = await self._get_statement(
           ^^^^^^^^^^^^^^^^^^^^^^^^^^
  File "/root/miniconda3/lib/python3.12/site-packages/asyncpg/connection.py", line 433, in _get_statement
    statement = await self._protocol.prepare(
                ^^^^^^^^^^^^^^^^^^^^^^^^^^^^^
  File "asyncpg/protocol/protocol.pyx", line 166, in prepare
asyncpg.exceptions.UndefinedTableError: relation "imgonly" does not exist
[2024-08-13 05:20:39] [ERROR   ] discord.client: Ignoring exception in on_message
Traceback (most recent call last):
  File "/root/miniconda3/lib/python3.12/site-packages/discord/client.py", line 450, in _run_event
    await coro(*args, **kwargs)
  File "/root/AkariBot/events/messages.py", line 383, in imageonly_check
    if await self.bot.db.fetchrow(
       ^^^^^^^^^^^^^^^^^^^^^^^^^^^
  File "/root/miniconda3/lib/python3.12/site-packages/asyncpg/pool.py", line 601, in fetchrow
    return await con.fetchrow(
           ^^^^^^^^^^^^^^^^^^^
  File "/root/miniconda3/lib/python3.12/site-packages/asyncpg/connection.py", line 749, in fetchrow
    data = await self._execute(
           ^^^^^^^^^^^^^^^^^^^^
  File "/root/miniconda3/lib/python3.12/site-packages/asyncpg/connection.py", line 1794, in _execute
    result, _ = await self.__execute(
                ^^^^^^^^^^^^^^^^^^^^^
  File "/root/miniconda3/lib/python3.12/site-packages/asyncpg/connection.py", line 1892, in __execute
    result, stmt = await self._do_execute(
                   ^^^^^^^^^^^^^^^^^^^^^^^
  File "/root/miniconda3/lib/python3.12/site-packages/asyncpg/connection.py", line 1925, in _do_execute
    stmt = await self._get_statement(
           ^^^^^^^^^^^^^^^^^^^^^^^^^^
  File "/root/miniconda3/lib/python3.12/site-packages/asyncpg/connection.py", line 433, in _get_statement
    statement = await self._protocol.prepare(
                ^^^^^^^^^^^^^^^^^^^^^^^^^^^^^
  File "asyncpg/protocol/protocol.pyx", line 166, in prepare
asyncpg.exceptions.UndefinedTableError: relation "imgonly" does not exist
[2024-08-13 05:20:40] [ERROR   ] discord.client: Ignoring exception in on_message
Traceback (most recent call last):
  File "/root/miniconda3/lib/python3.12/site-packages/discord/client.py", line 450, in _run_event
    await coro(*args, **kwargs)
  File "/root/AkariBot/events/messages.py", line 383, in imageonly_check
    if await self.bot.db.fetchrow(
       ^^^^^^^^^^^^^^^^^^^^^^^^^^^
  File "/root/miniconda3/lib/python3.12/site-packages/asyncpg/pool.py", line 601, in fetchrow
    return await con.fetchrow(
           ^^^^^^^^^^^^^^^^^^^
  File "/root/miniconda3/lib/python3.12/site-packages/asyncpg/connection.py", line 749, in fetchrow
    data = await self._execute(
           ^^^^^^^^^^^^^^^^^^^^
  File "/root/miniconda3/lib/python3.12/site-packages/asyncpg/connection.py", line 1794, in _execute
    result, _ = await self.__execute(
                ^^^^^^^^^^^^^^^^^^^^^
  File "/root/miniconda3/lib/python3.12/site-packages/asyncpg/connection.py", line 1892, in __execute
    result, stmt = await self._do_execute(
                   ^^^^^^^^^^^^^^^^^^^^^^^
  File "/root/miniconda3/lib/python3.12/site-packages/asyncpg/connection.py", line 1925, in _do_execute
    stmt = await self._get_statement(
           ^^^^^^^^^^^^^^^^^^^^^^^^^^
  File "/root/miniconda3/lib/python3.12/site-packages/asyncpg/connection.py", line 433, in _get_statement
    statement = await self._protocol.prepare(
                ^^^^^^^^^^^^^^^^^^^^^^^^^^^^^
  File "asyncpg/protocol/protocol.pyx", line 166, in prepare
asyncpg.exceptions.UndefinedTableError: relation "imgonly" does not exist
[2024-08-13 05:20:41] [ERROR   ] discord.client: Ignoring exception in on_message
Traceback (most recent call last):
  File "/root/miniconda3/lib/python3.12/site-packages/discord/client.py", line 450, in _run_event
    await coro(*args, **kwargs)
  File "/root/AkariBot/events/messages.py", line 383, in imageonly_check
    if await self.bot.db.fetchrow(
       ^^^^^^^^^^^^^^^^^^^^^^^^^^^
  File "/root/miniconda3/lib/python3.12/site-packages/asyncpg/pool.py", line 601, in fetchrow
    return await con.fetchrow(
           ^^^^^^^^^^^^^^^^^^^
  File "/root/miniconda3/lib/python3.12/site-packages/asyncpg/connection.py", line 749, in fetchrow
    data = await self._execute(
           ^^^^^^^^^^^^^^^^^^^^
  File "/root/miniconda3/lib/python3.12/site-packages/asyncpg/connection.py", line 1794, in _execute
    result, _ = await self.__execute(
                ^^^^^^^^^^^^^^^^^^^^^
  File "/root/miniconda3/lib/python3.12/site-packages/asyncpg/connection.py", line 1892, in __execute
    result, stmt = await self._do_execute(
                   ^^^^^^^^^^^^^^^^^^^^^^^
  File "/root/miniconda3/lib/python3.12/site-packages/asyncpg/connection.py", line 1925, in _do_execute
    stmt = await self._get_statement(
           ^^^^^^^^^^^^^^^^^^^^^^^^^^
  File "/root/miniconda3/lib/python3.12/site-packages/asyncpg/connection.py", line 433, in _get_statement
    statement = await self._protocol.prepare(
                ^^^^^^^^^^^^^^^^^^^^^^^^^^^^^
  File "asyncpg/protocol/protocol.pyx", line 166, in prepare
asyncpg.exceptions.UndefinedTableError: relation "imgonly" does not exist
[2024-08-13 05:20:41] [ERROR   ] discord.client: Ignoring exception in on_message
Traceback (most recent call last):
  File "/root/miniconda3/lib/python3.12/site-packages/discord/client.py", line 450, in _run_event
    await coro(*args, **kwargs)
  File "/root/AkariBot/events/messages.py", line 383, in imageonly_check
    if await self.bot.db.fetchrow(
       ^^^^^^^^^^^^^^^^^^^^^^^^^^^
  File "/root/miniconda3/lib/python3.12/site-packages/asyncpg/pool.py", line 601, in fetchrow
    return await con.fetchrow(
           ^^^^^^^^^^^^^^^^^^^
  File "/root/miniconda3/lib/python3.12/site-packages/asyncpg/connection.py", line 749, in fetchrow
    data = await self._execute(
           ^^^^^^^^^^^^^^^^^^^^
  File "/root/miniconda3/lib/python3.12/site-packages/asyncpg/connection.py", line 1794, in _execute
    result, _ = await self.__execute(
                ^^^^^^^^^^^^^^^^^^^^^
  File "/root/miniconda3/lib/python3.12/site-packages/asyncpg/connection.py", line 1892, in __execute
    result, stmt = await self._do_execute(
                   ^^^^^^^^^^^^^^^^^^^^^^^
  File "/root/miniconda3/lib/python3.12/site-packages/asyncpg/connection.py", line 1925, in _do_execute
    stmt = await self._get_statement(
           ^^^^^^^^^^^^^^^^^^^^^^^^^^
  File "/root/miniconda3/lib/python3.12/site-packages/asyncpg/connection.py", line 433, in _get_statement
    statement = await self._protocol.prepare(
                ^^^^^^^^^^^^^^^^^^^^^^^^^^^^^
  File "asyncpg/protocol/protocol.pyx", line 166, in prepare
asyncpg.exceptions.UndefinedTableError: relation "imgonly" does not exist
[2024-08-13 05:20:44] [ERROR   ] discord.client: Ignoring exception in on_message
Traceback (most recent call last):
  File "/root/miniconda3/lib/python3.12/site-packages/discord/client.py", line 450, in _run_event
    await coro(*args, **kwargs)
  File "/root/AkariBot/events/messages.py", line 383, in imageonly_check
    if await self.bot.db.fetchrow(
       ^^^^^^^^^^^^^^^^^^^^^^^^^^^
  File "/root/miniconda3/lib/python3.12/site-packages/asyncpg/pool.py", line 601, in fetchrow
    return await con.fetchrow(
           ^^^^^^^^^^^^^^^^^^^
  File "/root/miniconda3/lib/python3.12/site-packages/asyncpg/connection.py", line 749, in fetchrow
    data = await self._execute(
           ^^^^^^^^^^^^^^^^^^^^
  File "/root/miniconda3/lib/python3.12/site-packages/asyncpg/connection.py", line 1794, in _execute
    result, _ = await self.__execute(
                ^^^^^^^^^^^^^^^^^^^^^
  File "/root/miniconda3/lib/python3.12/site-packages/asyncpg/connection.py", line 1892, in __execute
    result, stmt = await self._do_execute(
                   ^^^^^^^^^^^^^^^^^^^^^^^
  File "/root/miniconda3/lib/python3.12/site-packages/asyncpg/connection.py", line 1925, in _do_execute
    stmt = await self._get_statement(
           ^^^^^^^^^^^^^^^^^^^^^^^^^^
  File "/root/miniconda3/lib/python3.12/site-packages/asyncpg/connection.py", line 433, in _get_statement
    statement = await self._protocol.prepare(
                ^^^^^^^^^^^^^^^^^^^^^^^^^^^^^
  File "asyncpg/protocol/protocol.pyx", line 166, in prepare
asyncpg.exceptions.UndefinedTableError: relation "imgonly" does not exist
[2024-08-13 05:20:48] [ERROR   ] discord.client: Ignoring exception in on_message
Traceback (most recent call last):
  File "/root/miniconda3/lib/python3.12/site-packages/discord/client.py", line 450, in _run_event
    await coro(*args, **kwargs)
  File "/root/AkariBot/events/messages.py", line 383, in imageonly_check
    if await self.bot.db.fetchrow(
       ^^^^^^^^^^^^^^^^^^^^^^^^^^^
  File "/root/miniconda3/lib/python3.12/site-packages/asyncpg/pool.py", line 601, in fetchrow
    return await con.fetchrow(
           ^^^^^^^^^^^^^^^^^^^
  File "/root/miniconda3/lib/python3.12/site-packages/asyncpg/connection.py", line 749, in fetchrow
    data = await self._execute(
           ^^^^^^^^^^^^^^^^^^^^
  File "/root/miniconda3/lib/python3.12/site-packages/asyncpg/connection.py", line 1794, in _execute
    result, _ = await self.__execute(
                ^^^^^^^^^^^^^^^^^^^^^
  File "/root/miniconda3/lib/python3.12/site-packages/asyncpg/connection.py", line 1892, in __execute
    result, stmt = await self._do_execute(
                   ^^^^^^^^^^^^^^^^^^^^^^^
  File "/root/miniconda3/lib/python3.12/site-packages/asyncpg/connection.py", line 1925, in _do_execute
    stmt = await self._get_statement(
           ^^^^^^^^^^^^^^^^^^^^^^^^^^
  File "/root/miniconda3/lib/python3.12/site-packages/asyncpg/connection.py", line 433, in _get_statement
    statement = await self._protocol.prepare(
                ^^^^^^^^^^^^^^^^^^^^^^^^^^^^^
  File "asyncpg/protocol/protocol.pyx", line 166, in prepare
asyncpg.exceptions.UndefinedTableError: relation "imgonly" does not exist
[2024-08-13 05:20:51] [ERROR   ] discord.client: Ignoring exception in on_message
Traceback (most recent call last):
  File "/root/miniconda3/lib/python3.12/site-packages/discord/client.py", line 450, in _run_event
    await coro(*args, **kwargs)
  File "/root/AkariBot/events/messages.py", line 383, in imageonly_check
    if await self.bot.db.fetchrow(
       ^^^^^^^^^^^^^^^^^^^^^^^^^^^
  File "/root/miniconda3/lib/python3.12/site-packages/asyncpg/pool.py", line 601, in fetchrow
    return await con.fetchrow(
           ^^^^^^^^^^^^^^^^^^^
  File "/root/miniconda3/lib/python3.12/site-packages/asyncpg/connection.py", line 749, in fetchrow
    data = await self._execute(
           ^^^^^^^^^^^^^^^^^^^^
  File "/root/miniconda3/lib/python3.12/site-packages/asyncpg/connection.py", line 1794, in _execute
    result, _ = await self.__execute(
                ^^^^^^^^^^^^^^^^^^^^^
  File "/root/miniconda3/lib/python3.12/site-packages/asyncpg/connection.py", line 1892, in __execute
    result, stmt = await self._do_execute(
                   ^^^^^^^^^^^^^^^^^^^^^^^
  File "/root/miniconda3/lib/python3.12/site-packages/asyncpg/connection.py", line 1925, in _do_execute
    stmt = await self._get_statement(
           ^^^^^^^^^^^^^^^^^^^^^^^^^^
  File "/root/miniconda3/lib/python3.12/site-packages/asyncpg/connection.py", line 433, in _get_statement
    statement = await self._protocol.prepare(
                ^^^^^^^^^^^^^^^^^^^^^^^^^^^^^
  File "asyncpg/protocol/protocol.pyx", line 166, in prepare
asyncpg.exceptions.UndefinedTableError: relation "imgonly" does not exist
[2024-08-13 05:20:55] [ERROR   ] discord.client: Ignoring exception in on_message
Traceback (most recent call last):
  File "/root/miniconda3/lib/python3.12/site-packages/discord/client.py", line 450, in _run_event
    await coro(*args, **kwargs)
  File "/root/AkariBot/events/messages.py", line 383, in imageonly_check
    if await self.bot.db.fetchrow(
       ^^^^^^^^^^^^^^^^^^^^^^^^^^^
  File "/root/miniconda3/lib/python3.12/site-packages/asyncpg/pool.py", line 601, in fetchrow
    return await con.fetchrow(
           ^^^^^^^^^^^^^^^^^^^
  File "/root/miniconda3/lib/python3.12/site-packages/asyncpg/connection.py", line 749, in fetchrow
    data = await self._execute(
           ^^^^^^^^^^^^^^^^^^^^
  File "/root/miniconda3/lib/python3.12/site-packages/asyncpg/connection.py", line 1794, in _execute
    result, _ = await self.__execute(
                ^^^^^^^^^^^^^^^^^^^^^
  File "/root/miniconda3/lib/python3.12/site-packages/asyncpg/connection.py", line 1892, in __execute
    result, stmt = await self._do_execute(
                   ^^^^^^^^^^^^^^^^^^^^^^^
  File "/root/miniconda3/lib/python3.12/site-packages/asyncpg/connection.py", line 1925, in _do_execute
    stmt = await self._get_statement(
           ^^^^^^^^^^^^^^^^^^^^^^^^^^
  File "/root/miniconda3/lib/python3.12/site-packages/asyncpg/connection.py", line 433, in _get_statement
    statement = await self._protocol.prepare(
                ^^^^^^^^^^^^^^^^^^^^^^^^^^^^^
  File "asyncpg/protocol/protocol.pyx", line 166, in prepare
asyncpg.exceptions.UndefinedTableError: relation "imgonly" does not exist
[2024-08-13 05:20:58] [ERROR   ] discord.client: Ignoring exception in on_message
Traceback (most recent call last):
  File "/root/miniconda3/lib/python3.12/site-packages/discord/client.py", line 450, in _run_event
    await coro(*args, **kwargs)
  File "/root/AkariBot/events/messages.py", line 383, in imageonly_check
    if await self.bot.db.fetchrow(
       ^^^^^^^^^^^^^^^^^^^^^^^^^^^
  File "/root/miniconda3/lib/python3.12/site-packages/asyncpg/pool.py", line 601, in fetchrow
    return await con.fetchrow(
           ^^^^^^^^^^^^^^^^^^^
  File "/root/miniconda3/lib/python3.12/site-packages/asyncpg/connection.py", line 749, in fetchrow
    data = await self._execute(
           ^^^^^^^^^^^^^^^^^^^^
  File "/root/miniconda3/lib/python3.12/site-packages/asyncpg/connection.py", line 1794, in _execute
    result, _ = await self.__execute(
                ^^^^^^^^^^^^^^^^^^^^^
  File "/root/miniconda3/lib/python3.12/site-packages/asyncpg/connection.py", line 1892, in __execute
    result, stmt = await self._do_execute(
                   ^^^^^^^^^^^^^^^^^^^^^^^
  File "/root/miniconda3/lib/python3.12/site-packages/asyncpg/connection.py", line 1925, in _do_execute
    stmt = await self._get_statement(
           ^^^^^^^^^^^^^^^^^^^^^^^^^^
  File "/root/miniconda3/lib/python3.12/site-packages/asyncpg/connection.py", line 433, in _get_statement
    statement = await self._protocol.prepare(
                ^^^^^^^^^^^^^^^^^^^^^^^^^^^^^
  File "asyncpg/protocol/protocol.pyx", line 166, in prepare
asyncpg.exceptions.UndefinedTableError: relation "imgonly" does not exist
[2024-08-13 05:21:02] [ERROR   ] discord.client: Ignoring exception in on_message
Traceback (most recent call last):
  File "/root/miniconda3/lib/python3.12/site-packages/discord/client.py", line 450, in _run_event
    await coro(*args, **kwargs)
  File "/root/AkariBot/events/messages.py", line 383, in imageonly_check
    if await self.bot.db.fetchrow(
       ^^^^^^^^^^^^^^^^^^^^^^^^^^^
  File "/root/miniconda3/lib/python3.12/site-packages/asyncpg/pool.py", line 601, in fetchrow
    return await con.fetchrow(
           ^^^^^^^^^^^^^^^^^^^
  File "/root/miniconda3/lib/python3.12/site-packages/asyncpg/connection.py", line 749, in fetchrow
    data = await self._execute(
           ^^^^^^^^^^^^^^^^^^^^
  File "/root/miniconda3/lib/python3.12/site-packages/asyncpg/connection.py", line 1794, in _execute
    result, _ = await self.__execute(
                ^^^^^^^^^^^^^^^^^^^^^
  File "/root/miniconda3/lib/python3.12/site-packages/asyncpg/connection.py", line 1892, in __execute
    result, stmt = await self._do_execute(
                   ^^^^^^^^^^^^^^^^^^^^^^^
  File "/root/miniconda3/lib/python3.12/site-packages/asyncpg/connection.py", line 1925, in _do_execute
    stmt = await self._get_statement(
           ^^^^^^^^^^^^^^^^^^^^^^^^^^
  File "/root/miniconda3/lib/python3.12/site-packages/asyncpg/connection.py", line 433, in _get_statement
    statement = await self._protocol.prepare(
                ^^^^^^^^^^^^^^^^^^^^^^^^^^^^^
  File "asyncpg/protocol/protocol.pyx", line 166, in prepare
asyncpg.exceptions.UndefinedTableError: relation "imgonly" does not exist
[2024-08-13 05:21:03] [ERROR   ] discord.client: Ignoring exception in on_message
Traceback (most recent call last):
  File "/root/miniconda3/lib/python3.12/site-packages/discord/client.py", line 450, in _run_event
    await coro(*args, **kwargs)
  File "/root/AkariBot/events/messages.py", line 383, in imageonly_check
    if await self.bot.db.fetchrow(
       ^^^^^^^^^^^^^^^^^^^^^^^^^^^
  File "/root/miniconda3/lib/python3.12/site-packages/asyncpg/pool.py", line 601, in fetchrow
    return await con.fetchrow(
           ^^^^^^^^^^^^^^^^^^^
  File "/root/miniconda3/lib/python3.12/site-packages/asyncpg/connection.py", line 749, in fetchrow
    data = await self._execute(
           ^^^^^^^^^^^^^^^^^^^^
  File "/root/miniconda3/lib/python3.12/site-packages/asyncpg/connection.py", line 1794, in _execute
    result, _ = await self.__execute(
                ^^^^^^^^^^^^^^^^^^^^^
  File "/root/miniconda3/lib/python3.12/site-packages/asyncpg/connection.py", line 1892, in __execute
    result, stmt = await self._do_execute(
                   ^^^^^^^^^^^^^^^^^^^^^^^
  File "/root/miniconda3/lib/python3.12/site-packages/asyncpg/connection.py", line 1925, in _do_execute
    stmt = await self._get_statement(
           ^^^^^^^^^^^^^^^^^^^^^^^^^^
  File "/root/miniconda3/lib/python3.12/site-packages/asyncpg/connection.py", line 433, in _get_statement
    statement = await self._protocol.prepare(
                ^^^^^^^^^^^^^^^^^^^^^^^^^^^^^
  File "asyncpg/protocol/protocol.pyx", line 166, in prepare
asyncpg.exceptions.UndefinedTableError: relation "imgonly" does not exist
[2024-08-13 05:21:03] [ERROR   ] discord.client: Ignoring exception in on_message
Traceback (most recent call last):
  File "/root/miniconda3/lib/python3.12/site-packages/discord/client.py", line 450, in _run_event
    await coro(*args, **kwargs)
  File "/root/AkariBot/events/messages.py", line 383, in imageonly_check
    if await self.bot.db.fetchrow(
       ^^^^^^^^^^^^^^^^^^^^^^^^^^^
  File "/root/miniconda3/lib/python3.12/site-packages/asyncpg/pool.py", line 601, in fetchrow
    return await con.fetchrow(
           ^^^^^^^^^^^^^^^^^^^
  File "/root/miniconda3/lib/python3.12/site-packages/asyncpg/connection.py", line 749, in fetchrow
    data = await self._execute(
           ^^^^^^^^^^^^^^^^^^^^
  File "/root/miniconda3/lib/python3.12/site-packages/asyncpg/connection.py", line 1794, in _execute
    result, _ = await self.__execute(
                ^^^^^^^^^^^^^^^^^^^^^
  File "/root/miniconda3/lib/python3.12/site-packages/asyncpg/connection.py", line 1892, in __execute
    result, stmt = await self._do_execute(
                   ^^^^^^^^^^^^^^^^^^^^^^^
  File "/root/miniconda3/lib/python3.12/site-packages/asyncpg/connection.py", line 1925, in _do_execute
    stmt = await self._get_statement(
           ^^^^^^^^^^^^^^^^^^^^^^^^^^
  File "/root/miniconda3/lib/python3.12/site-packages/asyncpg/connection.py", line 433, in _get_statement
    statement = await self._protocol.prepare(
                ^^^^^^^^^^^^^^^^^^^^^^^^^^^^^
  File "asyncpg/protocol/protocol.pyx", line 166, in prepare
asyncpg.exceptions.UndefinedTableError: relation "imgonly" does not exist
[2024-08-13 05:21:04] [ERROR   ] discord.client: Ignoring exception in on_message
Traceback (most recent call last):
  File "/root/miniconda3/lib/python3.12/site-packages/discord/client.py", line 450, in _run_event
    await coro(*args, **kwargs)
  File "/root/AkariBot/events/messages.py", line 383, in imageonly_check
    if await self.bot.db.fetchrow(
       ^^^^^^^^^^^^^^^^^^^^^^^^^^^
  File "/root/miniconda3/lib/python3.12/site-packages/asyncpg/pool.py", line 601, in fetchrow
    return await con.fetchrow(
           ^^^^^^^^^^^^^^^^^^^
  File "/root/miniconda3/lib/python3.12/site-packages/asyncpg/connection.py", line 749, in fetchrow
    data = await self._execute(
           ^^^^^^^^^^^^^^^^^^^^
  File "/root/miniconda3/lib/python3.12/site-packages/asyncpg/connection.py", line 1794, in _execute
    result, _ = await self.__execute(
                ^^^^^^^^^^^^^^^^^^^^^
  File "/root/miniconda3/lib/python3.12/site-packages/asyncpg/connection.py", line 1892, in __execute
    result, stmt = await self._do_execute(
                   ^^^^^^^^^^^^^^^^^^^^^^^
  File "/root/miniconda3/lib/python3.12/site-packages/asyncpg/connection.py", line 1925, in _do_execute
    stmt = await self._get_statement(
           ^^^^^^^^^^^^^^^^^^^^^^^^^^
  File "/root/miniconda3/lib/python3.12/site-packages/asyncpg/connection.py", line 433, in _get_statement
    statement = await self._protocol.prepare(
                ^^^^^^^^^^^^^^^^^^^^^^^^^^^^^
  File "asyncpg/protocol/protocol.pyx", line 166, in prepare
asyncpg.exceptions.UndefinedTableError: relation "imgonly" does not exist
[2024-08-13 05:21:06] [ERROR   ] discord.client: Ignoring exception in on_message
Traceback (most recent call last):
  File "/root/miniconda3/lib/python3.12/site-packages/discord/client.py", line 450, in _run_event
    await coro(*args, **kwargs)
  File "/root/AkariBot/events/messages.py", line 383, in imageonly_check
    if await self.bot.db.fetchrow(
       ^^^^^^^^^^^^^^^^^^^^^^^^^^^
  File "/root/miniconda3/lib/python3.12/site-packages/asyncpg/pool.py", line 601, in fetchrow
    return await con.fetchrow(
           ^^^^^^^^^^^^^^^^^^^
  File "/root/miniconda3/lib/python3.12/site-packages/asyncpg/connection.py", line 749, in fetchrow
    data = await self._execute(
           ^^^^^^^^^^^^^^^^^^^^
  File "/root/miniconda3/lib/python3.12/site-packages/asyncpg/connection.py", line 1794, in _execute
    result, _ = await self.__execute(
                ^^^^^^^^^^^^^^^^^^^^^
  File "/root/miniconda3/lib/python3.12/site-packages/asyncpg/connection.py", line 1892, in __execute
    result, stmt = await self._do_execute(
                   ^^^^^^^^^^^^^^^^^^^^^^^
  File "/root/miniconda3/lib/python3.12/site-packages/asyncpg/connection.py", line 1925, in _do_execute
    stmt = await self._get_statement(
           ^^^^^^^^^^^^^^^^^^^^^^^^^^
  File "/root/miniconda3/lib/python3.12/site-packages/asyncpg/connection.py", line 433, in _get_statement
    statement = await self._protocol.prepare(
                ^^^^^^^^^^^^^^^^^^^^^^^^^^^^^
  File "asyncpg/protocol/protocol.pyx", line 166, in prepare
asyncpg.exceptions.UndefinedTableError: relation "imgonly" does not exist
[2024-08-13 05:21:07] [ERROR   ] discord.client: Ignoring exception in on_message
Traceback (most recent call last):
  File "/root/miniconda3/lib/python3.12/site-packages/discord/client.py", line 450, in _run_event
    await coro(*args, **kwargs)
  File "/root/AkariBot/events/messages.py", line 383, in imageonly_check
    if await self.bot.db.fetchrow(
       ^^^^^^^^^^^^^^^^^^^^^^^^^^^
  File "/root/miniconda3/lib/python3.12/site-packages/asyncpg/pool.py", line 601, in fetchrow
    return await con.fetchrow(
           ^^^^^^^^^^^^^^^^^^^
  File "/root/miniconda3/lib/python3.12/site-packages/asyncpg/connection.py", line 749, in fetchrow
    data = await self._execute(
           ^^^^^^^^^^^^^^^^^^^^
  File "/root/miniconda3/lib/python3.12/site-packages/asyncpg/connection.py", line 1794, in _execute
    result, _ = await self.__execute(
                ^^^^^^^^^^^^^^^^^^^^^
  File "/root/miniconda3/lib/python3.12/site-packages/asyncpg/connection.py", line 1892, in __execute
    result, stmt = await self._do_execute(
                   ^^^^^^^^^^^^^^^^^^^^^^^
  File "/root/miniconda3/lib/python3.12/site-packages/asyncpg/connection.py", line 1925, in _do_execute
    stmt = await self._get_statement(
           ^^^^^^^^^^^^^^^^^^^^^^^^^^
  File "/root/miniconda3/lib/python3.12/site-packages/asyncpg/connection.py", line 433, in _get_statement
    statement = await self._protocol.prepare(
                ^^^^^^^^^^^^^^^^^^^^^^^^^^^^^
  File "asyncpg/protocol/protocol.pyx", line 166, in prepare
asyncpg.exceptions.UndefinedTableError: relation "imgonly" does not exist
[2024-08-13 05:21:15] [ERROR   ] discord.client: Ignoring exception in on_message
Traceback (most recent call last):
  File "/root/miniconda3/lib/python3.12/site-packages/discord/client.py", line 450, in _run_event
    await coro(*args, **kwargs)
  File "/root/AkariBot/events/messages.py", line 383, in imageonly_check
    if await self.bot.db.fetchrow(
       ^^^^^^^^^^^^^^^^^^^^^^^^^^^
  File "/root/miniconda3/lib/python3.12/site-packages/asyncpg/pool.py", line 601, in fetchrow
    return await con.fetchrow(
           ^^^^^^^^^^^^^^^^^^^
  File "/root/miniconda3/lib/python3.12/site-packages/asyncpg/connection.py", line 749, in fetchrow
    data = await self._execute(
           ^^^^^^^^^^^^^^^^^^^^
  File "/root/miniconda3/lib/python3.12/site-packages/asyncpg/connection.py", line 1794, in _execute
    result, _ = await self.__execute(
                ^^^^^^^^^^^^^^^^^^^^^
  File "/root/miniconda3/lib/python3.12/site-packages/asyncpg/connection.py", line 1892, in __execute
    result, stmt = await self._do_execute(
                   ^^^^^^^^^^^^^^^^^^^^^^^
  File "/root/miniconda3/lib/python3.12/site-packages/asyncpg/connection.py", line 1925, in _do_execute
    stmt = await self._get_statement(
           ^^^^^^^^^^^^^^^^^^^^^^^^^^
  File "/root/miniconda3/lib/python3.12/site-packages/asyncpg/connection.py", line 433, in _get_statement
    statement = await self._protocol.prepare(
                ^^^^^^^^^^^^^^^^^^^^^^^^^^^^^
  File "asyncpg/protocol/protocol.pyx", line 166, in prepare
asyncpg.exceptions.UndefinedTableError: relation "imgonly" does not exist
[2024-08-13 05:21:15] [ERROR   ] discord.client: Ignoring exception in on_message
Traceback (most recent call last):
  File "/root/miniconda3/lib/python3.12/site-packages/discord/client.py", line 450, in _run_event
    await coro(*args, **kwargs)
  File "/root/AkariBot/events/messages.py", line 383, in imageonly_check
    if await self.bot.db.fetchrow(
       ^^^^^^^^^^^^^^^^^^^^^^^^^^^
  File "/root/miniconda3/lib/python3.12/site-packages/asyncpg/pool.py", line 601, in fetchrow
    return await con.fetchrow(
           ^^^^^^^^^^^^^^^^^^^
  File "/root/miniconda3/lib/python3.12/site-packages/asyncpg/connection.py", line 749, in fetchrow
    data = await self._execute(
           ^^^^^^^^^^^^^^^^^^^^
  File "/root/miniconda3/lib/python3.12/site-packages/asyncpg/connection.py", line 1794, in _execute
    result, _ = await self.__execute(
                ^^^^^^^^^^^^^^^^^^^^^
  File "/root/miniconda3/lib/python3.12/site-packages/asyncpg/connection.py", line 1892, in __execute
    result, stmt = await self._do_execute(
                   ^^^^^^^^^^^^^^^^^^^^^^^
  File "/root/miniconda3/lib/python3.12/site-packages/asyncpg/connection.py", line 1925, in _do_execute
    stmt = await self._get_statement(
           ^^^^^^^^^^^^^^^^^^^^^^^^^^
  File "/root/miniconda3/lib/python3.12/site-packages/asyncpg/connection.py", line 433, in _get_statement
    statement = await self._protocol.prepare(
                ^^^^^^^^^^^^^^^^^^^^^^^^^^^^^
  File "asyncpg/protocol/protocol.pyx", line 166, in prepare
asyncpg.exceptions.UndefinedTableError: relation "imgonly" does not exist
[2024-08-13 05:21:16] [ERROR   ] discord.client: Ignoring exception in on_message
Traceback (most recent call last):
  File "/root/miniconda3/lib/python3.12/site-packages/discord/client.py", line 450, in _run_event
    await coro(*args, **kwargs)
  File "/root/AkariBot/events/messages.py", line 383, in imageonly_check
    if await self.bot.db.fetchrow(
       ^^^^^^^^^^^^^^^^^^^^^^^^^^^
  File "/root/miniconda3/lib/python3.12/site-packages/asyncpg/pool.py", line 601, in fetchrow
    return await con.fetchrow(
           ^^^^^^^^^^^^^^^^^^^
  File "/root/miniconda3/lib/python3.12/site-packages/asyncpg/connection.py", line 749, in fetchrow
    data = await self._execute(
           ^^^^^^^^^^^^^^^^^^^^
  File "/root/miniconda3/lib/python3.12/site-packages/asyncpg/connection.py", line 1794, in _execute
    result, _ = await self.__execute(
                ^^^^^^^^^^^^^^^^^^^^^
  File "/root/miniconda3/lib/python3.12/site-packages/asyncpg/connection.py", line 1892, in __execute
    result, stmt = await self._do_execute(
                   ^^^^^^^^^^^^^^^^^^^^^^^
  File "/root/miniconda3/lib/python3.12/site-packages/asyncpg/connection.py", line 1925, in _do_execute
    stmt = await self._get_statement(
           ^^^^^^^^^^^^^^^^^^^^^^^^^^
  File "/root/miniconda3/lib/python3.12/site-packages/asyncpg/connection.py", line 433, in _get_statement
    statement = await self._protocol.prepare(
                ^^^^^^^^^^^^^^^^^^^^^^^^^^^^^
  File "asyncpg/protocol/protocol.pyx", line 166, in prepare
asyncpg.exceptions.UndefinedTableError: relation "imgonly" does not exist
[2024-08-13 05:21:17] [ERROR   ] discord.client: Ignoring exception in on_message
Traceback (most recent call last):
  File "/root/miniconda3/lib/python3.12/site-packages/discord/client.py", line 450, in _run_event
    await coro(*args, **kwargs)
  File "/root/AkariBot/events/messages.py", line 383, in imageonly_check
    if await self.bot.db.fetchrow(
       ^^^^^^^^^^^^^^^^^^^^^^^^^^^
  File "/root/miniconda3/lib/python3.12/site-packages/asyncpg/pool.py", line 601, in fetchrow
    return await con.fetchrow(
           ^^^^^^^^^^^^^^^^^^^
  File "/root/miniconda3/lib/python3.12/site-packages/asyncpg/connection.py", line 749, in fetchrow
    data = await self._execute(
           ^^^^^^^^^^^^^^^^^^^^
  File "/root/miniconda3/lib/python3.12/site-packages/asyncpg/connection.py", line 1794, in _execute
    result, _ = await self.__execute(
                ^^^^^^^^^^^^^^^^^^^^^
  File "/root/miniconda3/lib/python3.12/site-packages/asyncpg/connection.py", line 1892, in __execute
    result, stmt = await self._do_execute(
                   ^^^^^^^^^^^^^^^^^^^^^^^
  File "/root/miniconda3/lib/python3.12/site-packages/asyncpg/connection.py", line 1925, in _do_execute
    stmt = await self._get_statement(
           ^^^^^^^^^^^^^^^^^^^^^^^^^^
  File "/root/miniconda3/lib/python3.12/site-packages/asyncpg/connection.py", line 433, in _get_statement
    statement = await self._protocol.prepare(
                ^^^^^^^^^^^^^^^^^^^^^^^^^^^^^
  File "asyncpg/protocol/protocol.pyx", line 166, in prepare
asyncpg.exceptions.UndefinedTableError: relation "imgonly" does not exist
[2024-08-13 05:21:18] [ERROR   ] discord.client: Ignoring exception in on_message
Traceback (most recent call last):
  File "/root/miniconda3/lib/python3.12/site-packages/discord/client.py", line 450, in _run_event
    await coro(*args, **kwargs)
  File "/root/AkariBot/events/messages.py", line 383, in imageonly_check
    if await self.bot.db.fetchrow(
       ^^^^^^^^^^^^^^^^^^^^^^^^^^^
  File "/root/miniconda3/lib/python3.12/site-packages/asyncpg/pool.py", line 601, in fetchrow
    return await con.fetchrow(
           ^^^^^^^^^^^^^^^^^^^
  File "/root/miniconda3/lib/python3.12/site-packages/asyncpg/connection.py", line 749, in fetchrow
    data = await self._execute(
           ^^^^^^^^^^^^^^^^^^^^
  File "/root/miniconda3/lib/python3.12/site-packages/asyncpg/connection.py", line 1794, in _execute
    result, _ = await self.__execute(
                ^^^^^^^^^^^^^^^^^^^^^
  File "/root/miniconda3/lib/python3.12/site-packages/asyncpg/connection.py", line 1892, in __execute
    result, stmt = await self._do_execute(
                   ^^^^^^^^^^^^^^^^^^^^^^^
  File "/root/miniconda3/lib/python3.12/site-packages/asyncpg/connection.py", line 1925, in _do_execute
    stmt = await self._get_statement(
           ^^^^^^^^^^^^^^^^^^^^^^^^^^
  File "/root/miniconda3/lib/python3.12/site-packages/asyncpg/connection.py", line 433, in _get_statement
    statement = await self._protocol.prepare(
                ^^^^^^^^^^^^^^^^^^^^^^^^^^^^^
  File "asyncpg/protocol/protocol.pyx", line 166, in prepare
asyncpg.exceptions.UndefinedTableError: relation "imgonly" does not exist
[2024-08-13 05:21:18] [ERROR   ] discord.client: Ignoring exception in on_message
Traceback (most recent call last):
  File "/root/miniconda3/lib/python3.12/site-packages/discord/client.py", line 450, in _run_event
    await coro(*args, **kwargs)
  File "/root/AkariBot/events/messages.py", line 383, in imageonly_check
    if await self.bot.db.fetchrow(
       ^^^^^^^^^^^^^^^^^^^^^^^^^^^
  File "/root/miniconda3/lib/python3.12/site-packages/asyncpg/pool.py", line 601, in fetchrow
    return await con.fetchrow(
           ^^^^^^^^^^^^^^^^^^^
  File "/root/miniconda3/lib/python3.12/site-packages/asyncpg/connection.py", line 749, in fetchrow
    data = await self._execute(
           ^^^^^^^^^^^^^^^^^^^^
  File "/root/miniconda3/lib/python3.12/site-packages/asyncpg/connection.py", line 1794, in _execute
    result, _ = await self.__execute(
                ^^^^^^^^^^^^^^^^^^^^^
  File "/root/miniconda3/lib/python3.12/site-packages/asyncpg/connection.py", line 1892, in __execute
    result, stmt = await self._do_execute(
                   ^^^^^^^^^^^^^^^^^^^^^^^
  File "/root/miniconda3/lib/python3.12/site-packages/asyncpg/connection.py", line 1925, in _do_execute
    stmt = await self._get_statement(
           ^^^^^^^^^^^^^^^^^^^^^^^^^^
  File "/root/miniconda3/lib/python3.12/site-packages/asyncpg/connection.py", line 433, in _get_statement
    statement = await self._protocol.prepare(
                ^^^^^^^^^^^^^^^^^^^^^^^^^^^^^
  File "asyncpg/protocol/protocol.pyx", line 166, in prepare
asyncpg.exceptions.UndefinedTableError: relation "imgonly" does not exist
